Workbook
Name Базис_1: Основа!$C$3
Name Базис_10: Основа!$C$12
Name Базис_100: Основа!$L$12
Name Базис_101: Основа!$M$3
Name Базис_102: Основа!$M$4
Name Базис_103: Основа!$M$5
Name Базис_104: Основа!$M$6
Name Базис_105: Основа!$M$7
Name Базис_106: Основа!$M$8
Name Базис_107: Основа!$M$9
Name Базис_108: Основа!$M$10
Name Базис_109: Основа!$M$11
Name Базис_11: Основа!$D$3
Name Базис_110: Основа!$M$12
Name Базис_12: Основа!$D$4
Name Базис_13: Основа!$D$5
Name Базис_14: Основа!$D$6
Name Базис_15: Основа!$D$7
Name Базис_16: Основа!$D$8
Name Базис_17: Основа!$D$9
Name Базис_18: Основа!$D$10
Name Базис_19: Основа!$D$11
Name Базис_2: Основа!$C$4
Name Базис_20: Основа!$D$12
Name Базис_21: Основа!$E$3
Name Базис_22: Основа!$E$4
Name Базис_23: Основа!$E$5
Name Базис_24: Основа!$E$6
Name Базис_25: Основа!$E$7
Name Базис_26: Основа!$E$8
Name Базис_27: Основа!$E$9
Name Базис_28: Основа!$E$10
Name Базис_29: Основа!$E$11
Name Базис_3: Основа!$C$5
Name Базис_30: Основа!$E$12
Name Базис_31: Основа!$F$3
Name Базис_32: Основа!$F$4
Name Базис_33: Основа!$F$5
Name Базис_34: Основа!$F$6
Name Базис_35: Основа!$F$7
Name Базис_36: Основа!$F$8
Name Базис_37: Основа!$F$9
Name Базис_38: Основа!$F$10
Name Базис_39: Основа!$F$11
Name Базис_4: Основа!$C$6
Name Базис_40: Основа!$F$12
Name Базис_41: Основа!$G$3
Name Базис_42: Основа!$G$4
Name Базис_43: Основа!$G$5
Name Базис_44: Основа!$G$6
Name Базис_45: Основа!$G$7
Name Базис_46: Основа!$G$8
Name Базис_47: Основа!$G$9
Name Базис_48: Основа!$G$10
Name Базис_49: Основа!$G$11
Name Базис_5: Основа!$C$7
Name Базис_50: Основа!$G$12
Name Базис_51: Основа!$H$3
Name Базис_52: Основа!$H$4
Name Базис_53: Основа!$H$5

Sheet Основа
R1: Женщины | AH1: Мужчины
B2: Наименование показателей | C2: 2014 | D2: 2015 | E2: 2016 | F2: 2017 | G2: 2018 | H2: 2019 | I2: 2020 | J2: 2021 | K2: 2022 | L2: 2023 | M2: 2024 | N2: МИН | O2: СРЗНАЧ | P2: МАКС | R2: Наименование показателей | S2: 2014 | T2: 2015 | U2: 2016 | V2: 2017 | W2: 2018 | X2: 2019 | Y2: 2020 | Z2: 2021 | AA2: 2022 | AB2: 2023 | AC2: 2024 | AD2: МИН | AE2: СРЗНАЧ | AF2: МАКС | AH2: Наименование показателей | AI2: 2014 | AJ2: 2015 | AK2: 2016 | AL2: 2017 | AM2: 2018 | AN2: 2019 | AO2: 2020 | AP2: 2021 | AQ2: 2022 | AR2: 2023 | AS2: 2024 | AT2: МИН | AU2: СРЗНАЧ | AV2: МАКС
B3: Кыргызская Республика | C3: 58246 | D3: 56010 | E3: 55579 | F3: 57578 | G3: 70869 | H3: 76101 | I3: 76652 | J3: 75970 | K3: 74683 | L3: 67603 | M3: 50854 | N3: =MIN(Базис_1:Базис_101) -> 50854 | O3: =AVERAGE(Базис_1:Базис_101) -> 65467.727 | P3: =MAX(Базис_1:Базис_101) -> 76652 | R3: Кыргызская Республика | S3: 30330 | T3: 29747 | U3: 29473 | V3: 29282 | W3: 35359 | X3: 36819 | Y3: 35904 | Z3: 34302 | AA3: 33077 | AB3: 29798 | AC3: 22978 | AD3: =MIN(Базис_Ж_1:Базис_Ж_101) -> 22978 | AE3: =AVERAGE(Базис_Ж_1:Базис_Ж_101) -> 31551.727 | AF3: =MAX(Базис_Ж_1:Базис_Ж_101) -> 36819 | AH3: Кыргызская Республика | AI3: 27916 | AJ3: 26263 | AK3: 26106 | AL3: 28296 | AM3: 35510 | AN3: 39282 | AO3: 40748 | AP3: 41668 | AQ3: 41606 | AR3: 37805 | AS3: 27876 | AT3: =MIN(Базис_М_1:Базис_М_101) -> 26106 | AU3: =AVERAGE(Базис_М_1:Базис_М_101) -> 33916 | AV3: =MAX(Базис_М_1:Базис_М_101) -> 41668
B4: Баткенская область | C4: 6045 | D4: 5910 | E4: 4988 | F4: 6267 | G4: 8954 | H4: 10926 | I4: 9950 | J4: 9902 | K4: 13490 | L4: 14080 | M4: 8557 | N4: =MIN(Базис_2:Базис_102) -> 4988 | O4: =AVERAGE(Базис_2:Базис_102) -> 9006.2727 | P4: =MAX(Базис_2:Базис_102) -> 14080 | R4: Баткенская область | S4: 2095 | T4: 2229 | U4: 1835 | V4: 2024 | W4: 3607 | X4: 5139 | Y4: 4501 | Z4: 4247 | AA4: 5572 | AB4: 5834 | AC4: 3492 | AD4: =MIN(Базис_Ж_2:Базис_Ж_102) -> 1835 | AE4: =AVERAGE(Базис_Ж_2:Базис_Ж_102) -> 3688.6364 | AF4: =MAX(Базис_Ж_2:Базис_Ж_102) -> 5834 | AH4: Баткенская область | AI4: 3950 | AJ4: 3681 | AK4: 3153 | AL4: 4243 | AM4: 5347 | AN4: 5787 | AO4: 5449 | AP4: 5655 | AQ4: 7918 | AR4: 8246 | AS4: 5065 | AT4: =MIN(Базис_М_2:Базис_М_102) -> 3153 | AU4: =AVERAGE(Базис_М_2:Базис_М_102) -> 5317.6364 | AV4: =MAX(Базис_М_2:Базис_М_102) -> 8246
B5: Джалал-Абадская область | C5: 12801 | D5: 12318 | E5: 13775 | F5: 16811 | G5: 23471 | H5: 22723 | I5: 22479 | J5: 21711 | K5: 19744 | L5: 17218 | M5: 12384 | N5: =MIN(Базис_3:Базис_103) -> 12318 | O5: =AVERAGE(Базис_3:Базис_103) -> 17766.818 | P5: =MAX(Базис_3:Базис_103) -> 23471 | R5: Джалал-Абадская область | S5: 7215 | T5: 6854 | U5: 7332 | V5: 8034 | W5: 10838 | X5: 9885 | Y5: 9123 | Z5: 8504 | AA5: 7645 | AB5: 6382 | AC5: 4865 | AD5: =MIN(Базис_Ж_3:Базис_Ж_103) -> 4865 | AE5: =AVERAGE(Базис_Ж_3:Базис_Ж_103) -> 7879.7273 | AF5: =MAX(Базис_Ж_3:Базис_Ж_103) -> 10838 | AH5: Джалал-Абадская область | AI5: 5586 | AJ5: 5464 | AK5: 6443 | AL5: 8777 | AM5: 12633 | AN5: 12838 | AO5: 13356 | AP5: 13207 | AQ5: 12099 | AR5: 10836 | AS5: 7519 | AT5: =MIN(Базис_М_3:Базис_М_103) -> 5464 | AU5: =AVERAGE(Базис_М_3:Базис_М_103) -> 9887.0909 | AV5: =MAX(Базис_М_3:Базис_М_103) -> 13356
B6: Иссык-Кульская область | C6: 4281 | D6: 4510 | E6: 4660 | F6: 4197 | G6: 4202 | H6: 4320 | I6: 4491 | J6: 4241 | K6: 3733 | L6: 2761 | M6: 2245 | N6: =MIN(Базис_4:Базис_104) -> 2245 | O6: =AVERAGE(Базис_4:Базис_104) -> 3967.3636 | P6: =MAX(Базис_4:Базис_104) -> 4660 | R6: Иссык-Кульская область | S6: 2236 | T6: 2287 | U6: 2390 | V6: 2347 | W6: 2305 | X6: 2306 | Y6: 2366 | Z6: 2282 | AA6: 1973 | AB6: 1542 | AC6: 1178 | AD6: =MIN(Базис_Ж_4:Базис_Ж_104) -> 1178 | AE6: =AVERAGE(Базис_Ж_4:Базис_Ж_104) -> 2110.1818 | AF6: =MAX(Базис_Ж_4:Базис_Ж_104) -> 2390 | AH6: Иссык-Кульская область | AI6: 2045 | AJ6: 2223 | AK6: 2270 | AL6: 1850 | AM6: 1897 | AN6: 2014 | AO6: 2125 | AP6: 1959 | AQ6: 1760 | AR6: 1219 | AS6: 1067 | AT6: =MIN(Базис_М_4:Базис_М_104) -> 1067 | AU6: =AVERAGE(Базис_М_4:Базис_М_104) -> 1857.1818 | AV6: =MAX(Базис_М_4:Базис_М_104) -> 2270
B7: Нарынская Область | C7: 6148 | D7: 5426 | E7: 5442 | F7: 4087 | G7: 4068 | H7: 2878 | I7: 2853 | J7: 2781 | K7: 2482 | L7: 1977 | M7: 1560 | N7: =MIN(Базис_5:Базис_105) -> 1560 | O7: =AVERAGE(Базис_5:Базис_105) -> 3609.2727 | P7: =MAX(Базис_5:Базис_105) -> 6148 | R7: Нарынская область | S7: 3367 | T7: 3140 | U7: 3221 | V7: 2549 | W7: 2182 | X7: 1420 | Y7: 1402 | Z7: 1385 | AA7: 1229 | AB7: 995 | AC7: 793 | AD7: =MIN(Базис_Ж_5:Базис_Ж_105) -> 793 | AE7: =AVERAGE(Базис_Ж_5:Базис_Ж_105) -> 1971.1818 | AF7: =MAX(Базис_Ж_5:Базис_Ж_105) -> 3367 | AH7: Нарынская область | AI7: 2781 | AJ7: 2286 | AK7: 2221 | AL7: 1538 | AM7: 1886 | AN7: 1458 | AO7: 1451 | AP7: 1396 | AQ7: 1253 | AR7: 982 | AS7: 767 | AT7: =MIN(Базис_М_5:Базис_М_105) -> 767 | AU7: =AVERAGE(Базис_М_5:Базис_М_105) -> 1638.0909 | AV7: =MAX(Базис_М_5:Базис_М_105) -> 2781
B8: Ошская область | C8: 11894 | D8: 11165 | E8: 10971 | F8: 11724 | G8: 15564 | H8: 19479 | I8: 19977 | J8: 19444 | K8: 17556 | L8: 16376 | M8: 14010 | N8: =MIN(Базис_6:Базис_106) -> 10971 | O8: =AVERAGE(Базис_6:Базис_106) -> 15287.273 | P8: =MAX(Базис_6:Базис_106) -> 19977 | R8: Ошская область | S8: 4975 | T8: 4888 | U8: 5127 | V8: 5396 | W8: 7501 | X8: 8642 | Y8: 8747 | Z8: 8089 | AA8: 7166 | AB8: 6709 | AC8: 5701 | AD8: =MIN(Базис_Ж_6:Базис_Ж_106) -> 4888 | AE8: =AVERAGE(Базис_Ж_6:Базис_Ж_106) -> 6631 | AF8: =MAX(Базис_Ж_6:Базис_Ж_106) -> 8747 | AH8: Ошская область | AI8: 6919 | AJ8: 6277 | AK8: 5844 | AL8: 6328 | AM8: 8063 | AN8: 10837 | AO8: 11230 | AP8: 11355 | AQ8: 10390 | AR8: 9667 | AS8: 8309 | AT8: =MIN(Базис_М_6:Базис_М_106) -> 5844 | AU8: =AVERAGE(Базис_М_6:Базис_М_106) -> 8656.2727 | AV8: =MAX(Базис_М_6:Базис_М_106) -> 11355
B9: Таласская область | C9: 2033 | D9: 2043 | E9: 2288 | F9: 2280 | G9: 2823 | H9: 3019 | I9: 3050 | J9: 3115 | K9: 3185 | L9: 3274 | M9: 2637 | N9: =MIN(Базис_7:Базис_107) -> 2033 | O9: =AVERAGE(Базис_7:Базис_107) -> 2704.2727 | P9: =MAX(Базис_7:Базис_107) -> 3274 | R9: Таласская область | S9: 1253 | T9: 1377 | U9: 1510 | V9: 1555 | W9: 1780 | X9: 1808 | Y9: 1680 | Z9: 1595 | AA9: 1557 | AB9: 1607 | AC9: 1289 | AD9: =MIN(Базис_Ж_7:Базис_Ж_107) -> 1253 | AE9: =AVERAGE(Базис_Ж_7:Базис_Ж_107) -> 1546.4545 | AF9: =MAX(Базис_Ж_7:Базис_Ж_107) -> 1808 | AH9: Таласская область | AI9: 780 | AJ9: 666 | AK9: 778 | AL9: 725 | AM9: 1043 | AN9: 1211 | AO9: 1370 | AP9: 1520 | AQ9: 1628 | AR9: 1667 | AS9: 1348 | AT9: =MIN(Базис_М_7:Базис_М_107) -> 666 | AU9: =AVERAGE(Базис_М_7:Базис_М_107) -> 1157.8182 | AV9: =MAX(Базис_М_7:Базис_М_107) -> 1667
B10: Чуйская область | C10: 5529 | D10: 5297 | E10: 5114 | F10: 4864 | G10: 4400 | H10: 4155 | I10: 4829 | J10: 5416 | K10: 5155 | L10: 3659 | M10: 2197 | N10: =MIN(Базис_8:Базис_108) -> 2197 | O10: =AVERAGE(Базис_8:Базис_108) -> 4601.3636 | P10: =MAX(Базис_8:Базис_108) -> 5529 | R10: Чуйская область | S10: 3431 | T10: 3215 | U10: 2982 | V10: 2882 | W10: 2577 | X10: 2241 | Y10: 2571 | Z10: 2821 | AA10: 2583 | AB10: 1957 | AC10: 1303 | AD10: =MIN(Базис_Ж_8:Базис_Ж_108) -> 1303 | AE10: =AVERAGE(Базис_Ж_8:Базис_Ж_108) -> 2596.6364 | AF10: =MAX(Базис_Ж_8:Базис_Ж_108) -> 3431 | AH10: Чуйская область | AI10: 2098 | AJ10: 2082 | AK10: 2132 | AL10: 1982 | AM10: 1823 | AN10: 1914 | AO10: 2258 | AP10: 2595 | AQ10: 2572 | AR10: 1702 | AS10: 894 | AT10: =MIN(Базис_М_8:Базис_М_108) -> 894 | AU10: =AVERAGE(Базис_М_8:Базис_М_108) -> 2004.7273 | AV10: =MAX(Базис_М_8:Базис_М_108) -> 2595
B11: г.Бишкек | C11: 7316 | D11: 6894 | E11: 5927 | F11: 5078 | G11: 5059 | H11: 5938 | I11: 5932 | J11: 6004 | K11: 6273 | L11: 5330 | M11: 4310 | N11: =MIN(Базис_9:Базис_109) -> 4310 | O11: =AVERAGE(Базис_9:Базис_109) -> 5823.7273 | P11: =MAX(Базис_9:Базис_109) -> 7316 | R11: г.Бишкек | S11: 4737 | T11: 4604 | U11: 3910 | V11: 3403 | W11: 3396 | X11: 3841 | Y11: 3828 | Z11: 3703 | AA11: 3895 | AB11: 3340 | AC11: 2758 | AD11: =MIN(Базис_Ж_9:Базис_Ж_109) -> 2758 | AE11: =AVERAGE(Базис_Ж_9:Базис_Ж_109) -> 3765 | AF11: =MAX(Базис_Ж_9:Базис_Ж_109) -> 4737 | AH11: г.Бишкек | AI11: 2579 | AJ11: 2290 | AK11: 2017 | AL11: 1675 | AM11: 1663 | AN11: 2097 | AO11: 2104 | AP11: 2301 | AQ11: 2378 | AR11: 1990 | AS11: 1552 | AT11: =MIN(Базис_М_9:Базис_М_109) -> 1552 | AU11: =AVERAGE(Базис_М_9:Базис_М_109) -> 2058.7273 | AV11: =MAX(Базис_М_9:Базис_М_109) -> 2579
B12: г.Ош | C12: 2199 | D12: 2447 | E12: 2414 | F12: 2270 | G12: 2328 | H12: 2663 | I12: 3091 | J12: 3356 | K12: 3065 | L12: 2928 | M12: 2954 | N12: =MIN(Базис_10:Базис_110) -> 2199 | O12: =AVERAGE(Базис_10:Базис_110) -> 2701.3636 | P12: =MAX(Базис_10:Базис_110) -> 3356 | R12: г. Ош | S12: 1021 | T12: 1153 | U12: 1166 | V12: 1092 | W12: 1173 | X12: 1537 | Y12: 1686 | Z12: 1676 | AA12: 1457 | AB12: 1432 | AC12: 1599 | AD12: =MIN(Базис_Ж_10:Базис_Ж_110) -> 1021 | AE12: =AVERAGE(Базис_Ж_10:Базис_Ж_110) -> 1362.9091 | AF12: =MAX(Базис_Ж_10:Базис_Ж_110) -> 1686 | AH12: г. Ош | AI12: 1178 | AJ12: 1294 | AK12: 1248 | AL12: 1178 | AM12: 1155 | AN12: 1126 | AO12: 1405 | AP12: 1680 | AQ12: 1608 | AR12: 1496 | AS12: 1355 | AT12: =MIN(Базис_М_10:Базис_М_110) -> 1126 | AU12: =AVERAGE(Базис_М_10:Базис_М_110) -> 1338.4545 | AV12: =MAX(Базис_М_10:Базис_М_110) -> 1680
B14: Темп роста Цепной | R14: Темп роста Цепной | AH14: Темп роста Цепной
B15: Кыргызская Республика | D15: =Базис_11/Базис_1 -> 0.9616111 | E15: =Базис_21/Базис_11 -> 0.99230495 | F15: =Базис_31/Базис_21 -> 1.0359668 | G15: =Базис_41/Базис_31 -> 1.2308347 | H15: =Базис_51/Базис_41 -> 1.0738264 | I15: =Базис_61/Базис_51 -> 1.0072404 | J15: =Базис_71/Базис_61 -> 0.99110265 | K15: =Базис_81/Базис_71 -> 0.9830591 | L15: =Базис_91/Базис_81 -> 0.90519931 | M15: =Базис_101/Базис_91 -> 0.75224472 | N15: =Базис_11/Базис_1 -> 0.9616111 | O15: =Базис_21/Базис_11 -> 0.99230495 | P15: =Базис_31/Базис_21 -> 1.0359668 | R15: Кыргызская Республика | T15: =Базис_Ж_11/Базис_Ж_1 -> 0.98077811 | U15: =Базис_Ж_21/Базис_Ж_11 -> 0.99078899 | V15: =Базис_Ж_31/Базис_Ж_21 -> 0.99351949 | W15: =Базис_Ж_41/Базис_Ж_31 -> 1.2075336 | X15: =Базис_Ж_51/Базис_Ж_41 -> 1.0412908 | Y15: =Базис_Ж_61/Базис_Ж_51 -> 0.9751487 | Z15: =Базис_Ж_71/Базис_Ж_61 -> 0.95538102 | AA15: =Базис_Ж_81/Базис_Ж_71 -> 0.9642878 | AB15: =Базис_Ж_91/Базис_Ж_81 -> 0.90086767 | AC15: =Базис_Ж_101/Базис_Ж_91 -> 0.77112558 | AD15: =AD3/Базис_Ж_101 -> 1 | AE15: =AE3/AD3 -> 1.3731277 | AF15: =AF3/AE3 -> 1.1669409 | AH15: Кыргызская Республика | AJ15: =Базис_М_11/Базис_М_1 -> 0.94078665 | AK15: =Базис_М_21/Базис_М_11 -> 0.99402201 | AL15: =Базис_М_31/Базис_М_21 -> 1.0838888 | AM15: =Базис_М_41/Базис_М_31 -> 1.2549477 | AN15: =Базис_М_51/Базис_М_41 -> 1.1062236 | AO15: =Базис_М_61/Базис_М_51 -> 1.0373199 | AP15: =Базис_М_71/Базис_М_61 -> 1.0225778 | AQ15: =Базис_М_81/Базис_М_71 -> 0.99851205 | AR15: =Базис_М_91/Базис_М_81 -> 0.90864298 | AS15: =Базис_М_101/Базис_М_91 -> 0.73736278 | AT15: =AT3/Базис_М_101 -> 0.93650452 | AU15: =AU3/AT3 -> 1.2991649 | AV15: =AV3/AU3 -> 1.2285647
B16: Баткенская область | D16: =Базис_12/Базис_2 -> 0.97766749 | E16: =Базис_22/Базис_12 -> 0.84399323 | F16: =Базис_32/Базис_22 -> 1.2564154 | G16: =Базис_42/Базис_32 -> 1.4287538 | H16: =Базис_52/Базис_42 -> 1.2202368 | I16: =Базис_62/Базис_52 -> 0.91067179 | J16: =Базис_72/Базис_62 -> 0.99517588 | K16: =Базис_82/Базис_72 -> 1.362351 | L16: =Базис_92/Базис_82 -> 1.0437361 | M16: =Базис_102/Базис_92 -> 0.60774148 | N16: =Базис_12/Базис_2 -> 0.97766749 | O16: =Базис_22/Базис_12 -> 0.84399323 | P16: =Базис_32/Базис_22 -> 1.2564154 | R16: Баткенская область | T16: =Базис_Ж_12/Базис_Ж_2 -> 1.0639618 | U16: =Базис_Ж_22/Базис_Ж_12 -> 0.82323912 | V16: =Базис_Ж_32/Базис_Ж_22 -> 1.1029973 | W16: =Базис_Ж_42/Базис_Ж_32 -> 1.7821146 | X16: =Базис_Ж_52/Базис_Ж_42 -> 1.4247297 | Y16: =Базис_Ж_62/Базис_Ж_52 -> 0.87585133 | Z16: =Базис_Ж_72/Базис_Ж_62 -> 0.9435681 | AA16: =Базис_Ж_82/Базис_Ж_72 -> 1.3119849 | AB16: =Базис_Ж_92/Базис_Ж_82 -> 1.0470208 | AC16: =Базис_Ж_102/Базис_Ж_92 -> 0.59856016 | AD16: =AD4/Базис_Ж_102 -> 0.52548683 | AE16: =AE4/AD4 -> 2.0101561 | AF16: =AF4/AE4 -> 1.5816143 | AH16: Баткенская область | AJ16: =Базис_М_12/Базис_М_2 -> 0.93189873 | AK16: =Базис_М_22/Базис_М_12 -> 0.85656072 | AL16: =Базис_М_32/Базис_М_22 -> 1.3457025 | AM16: =Базис_М_42/Базис_М_32 -> 1.2601933 | AN16: =Базис_М_52/Базис_М_42 -> 1.0822891 | AO16: =Базис_М_62/Базис_М_52 -> 0.94159323 | AP16: =Базис_М_72/Базис_М_62 -> 1.0378051 | AQ16: =Базис_М_82/Базис_М_72 -> 1.4001768 | AR16: =Базис_М_92/Базис_М_82 -> 1.0414246 | AS16: =Базис_М_102/Базис_М_92 -> 0.61423721 | AT16: =AT4/Базис_М_102 -> 0.6225074 | AU16: =AU4/AT4 -> 1.6865323 | AV16: =AV4/AU4 -> 1.550689
B17: Джалал-Абадская область | D17: =Базис_13/Базис_3 -> 0.96226857 | E17: =Базис_23/Базис_13 -> 1.1182822 | F17: =Базис_33/Базис_23 -> 1.2203993 | G17: =Базис_43/Базис_33 -> 1.3961692 | H17: =Базис_53/Базис_43 -> 0.96813088 | I17: =Базис_63/Базис_53 -> 0.98926198 | J17: =Базис_73/Базис_63 -> 0.96583478 | K17: =Базис_83/Базис_73 -> 0.90940076 | L17: =Базис_93/Базис_83 -> 0.8720624 | M17: =Базис_103/Базис_93 -> 0.7192473 | N17: =Базис_13/Базис_3 -> 0.96226857 | O17: =Базис_23/Базис_13 -> 1.1182822 | P17: =Базис_33/Базис_23 -> 1.2203993 | R17: Джалал-Абадская область | T17: =Базис_Ж_13/Базис_Ж_3 -> 0.94996535 | U17: =Базис_Ж_23/Базис_Ж_13 -> 1.0697403 | V17: =Базис_Ж_33/Базис_Ж_23 -> 1.0957447 | W17: =Базис_Ж_43/Базис_Ж_33 -> 1.3490167 | X17: =Базис_Ж_53/Базис_Ж_43 -> 0.91206865 | Y17: =Базис_Ж_63/Базис_Ж_53 -> 0.92291351 | Z17: =Базис_Ж_73/Базис_Ж_63 -> 0.93214951 | AA17: =Базис_Ж_83/Базис_Ж_73 -> 0.89898871 | AB17: =Базис_Ж_93/Базис_Ж_83 -> 0.83479398 | AC17: =Базис_Ж_103/Базис_Ж_93 -> 0.76230022 | AD17: =AD5/Базис_Ж_103 -> 1 | AE17: =AE5/AD5 -> 1.6196767 | AF17: =AF5/AE5 -> 1.3754283 | AH17: Джалал-Абадская область | AJ17: =Базис_М_13/Базис_М_3 -> 0.97815968 | AK17: =Базис_М_23/Базис_М_13 -> 1.1791728 | AL17: =Базис_М_33/Базис_М_23 -> 1.3622536 | AM17: =Базис_М_43/Базис_М_33 -> 1.4393301 | AN17: =Базис_М_53/Базис_М_43 -> 1.0162273 | AO17: =Базис_М_63/Базис_М_53 -> 1.040349 | AP17: =Базис_М_73/Базис_М_63 -> 0.98884397 | AQ17: =Базис_М_83/Базис_М_73 -> 0.9161051 | AR17: =Базис_М_93/Базис_М_83 -> 0.89561121 | AS17: =Базис_М_103/Базис_М_93 -> 0.69389073 | AT17: =AT5/Базис_М_103 -> 0.72669238 | AU17: =AU5/AT5 -> 1.8094969 | AV17: =AV5/AU5 -> 1.3508524
B18: Иссык-Кульская область | D18: =Базис_14/Базис_4 -> 1.0534922 | E18: =Базис_24/Базис_14 -> 1.0332594 | F18: =Базис_34/Базис_24 -> 0.90064378 | G18: =Базис_44/Базис_34 -> 1.0011913 | H18: =Базис_54/Базис_44 -> 1.0280819 | I18: =Базис_64/Базис_54 -> 1.0395833 | J18: =Базис_74/Базис_64 -> 0.94433311 | K18: =Базис_84/Базис_74 -> 0.88021693 | L18: =Базис_94/Базис_84 -> 0.73961961 | M18: =Базис_104/Базис_94 -> 0.81311119 | N18: =Базис_14/Базис_4 -> 1.0534922 | O18: =Базис_24/Базис_14 -> 1.0332594 | P18: =Базис_34/Базис_24 -> 0.90064378 | R18: Иссык-Кульская область | T18: =Базис_Ж_14/Базис_Ж_4 -> 1.0228086 | U18: =Базис_Ж_24/Базис_Ж_14 -> 1.0450372 | V18: =Базис_Ж_34/Базис_Ж_24 -> 0.98200837 | W18: =Базис_Ж_44/Базис_Ж_34 -> 0.98210481 | X18: =Базис_Ж_54/Базис_Ж_44 -> 1.0004338 | Y18: =Базис_Ж_64/Базис_Ж_54 -> 1.0260191 | Z18: =Базис_Ж_74/Базис_Ж_64 -> 0.96449704 | AA18: =Базис_Ж_84/Базис_Ж_74 -> 0.86459246 | AB18: =Базис_Ж_94/Базис_Ж_84 -> 0.78155094 | AC18: =Базис_Ж_104/Базис_Ж_94 -> 0.76394293 | AD18: =AD6/Базис_Ж_104 -> 1 | AE18: =AE6/AD6 -> 1.7913258 | AF18: =AF6/AE6 -> 1.1326038 | AH18: Иссык-Кульская область | AJ18: =Базис_М_14/Базис_М_4 -> 1.0870416 | AK18: =Базис_М_24/Базис_М_14 -> 1.0211426 | AL18: =Базис_М_34/Базис_М_24 -> 0.81497797 | AM18: =Базис_М_44/Базис_М_34 -> 1.0254054 | AN18: =Базис_М_54/Базис_М_44 -> 1.0616763 | AO18: =Базис_М_64/Базис_М_54 -> 1.0551142 | AP18: =Базис_М_74/Базис_М_64 -> 0.92188235 | AQ18: =Базис_М_84/Базис_М_74 -> 0.89841756 | AR18: =Базис_М_94/Базис_М_84 -> 0.69261364 | AS18: =Базис_М_104/Базис_М_94 -> 0.87530763 | AT18: =AT6/Базис_М_104 -> 1 | AU18: =AU6/AT6 -> 1.740564 | AV18: =AV6/AU6 -> 1.2222821
B19: Нарынская Область | D19: =Базис_15/Базис_5 -> 0.88256344 | E19: =Базис_25/Базис_15 -> 1.0029488 | F19: =Базис_35/Базис_25 -> 0.75101066 | G19: =Базис_45/Базис_35 -> 0.99535111 | H19: =Базис_55/Базис_45 -> 0.70747296 | I19: =Базис_65/Базис_55 -> 0.99131341 | J19: =Базис_75/Базис_65 -> 0.97476341 | K19: =Базис_85/Базис_75 -> 0.89248472 | L19: =Базис_95/Базис_85 -> 0.79653505 | M19: =Базис_105/Базис_95 -> 0.78907436 | N19: =Базис_15/Базис_5 -> 0.88256344 | O19: =Базис_25/Базис_15 -> 1.0029488 | P19: =Базис_35/Базис_25 -> 0.75101066 | R19: Нарынская область | T19: =Базис_Ж_15/Базис_Ж_5 -> 0.93258093 | U19: =Базис_Ж_25/Базис_Ж_15 -> 1.0257962 | V19: =Базис_Ж_35/Базис_Ж_25 -> 0.79136914 | W19: =Базис_Ж_45/Базис_Ж_35 -> 0.85602197 | X19: =Базис_Ж_55/Базис_Ж_45 -> 0.6507791 | Y19: =Базис_Ж_65/Базис_Ж_55 -> 0.98732394 | Z19: =Базис_Ж_75/Базис_Ж_65 -> 0.98787447 | AA19: =Базис_Ж_85/Базис_Ж_75 -> 0.88736462 | AB19: =Базис_Ж_95/Базис_Ж_85 -> 0.8096013 | AC19: =Базис_Ж_105/Базис_Ж_95 -> 0.79698492 | AD19: =AD7/Базис_Ж_105 -> 1 | AE19: =AE7/AD7 -> 2.4857274 | AF19: =AF7/AE7 -> 1.7081123 | AH19: Нарынская область | AJ19: =Базис_М_15/Базис_М_5 -> 0.82200647 | AK19: =Базис_М_25/Базис_М_15 -> 0.97156605 | AL19: =Базис_М_35/Базис_М_25 -> 0.69248086 | AM19: =Базис_М_45/Базис_М_35 -> 1.2262679 | AN19: =Базис_М_55/Базис_М_45 -> 0.77306469 | AO19: =Базис_М_65/Базис_М_55 -> 0.9951989 | AP19: =Базис_М_75/Базис_М_65 -> 0.96209511 | AQ19: =Базис_М_85/Базис_М_75 -> 0.89756447 | AR19: =Базис_М_95/Базис_М_85 -> 0.78371907 | AS19: =Базис_М_105/Базис_М_95 -> 0.78105906 | AT19: =AT7/Базис_М_105 -> 1 | AU19: =AU7/AT7 -> 2.1357117 | AV19: =AV7/AU7 -> 1.697708
B20: Ошская область | D20: =Базис_16/Базис_6 -> 0.93870859 | E20: =Базис_26/Базис_16 -> 0.98262427 | F20: =Базис_36/Базис_26 -> 1.0686355 | G20: =Базис_46/Базис_36 -> 1.3275333 | H20: =Базис_56/Базис_46 -> 1.251542 | I20: =Базис_66/Базис_56 -> 1.025566 | J20: =Базис_76/Базис_66 -> 0.97331932 | K20: =Базис_86/Базис_76 -> 0.90290064 | L20: =Базис_96/Базис_86 -> 0.93278651 | M20: =Базис_106/Базис_96 -> 0.85552027 | N20: =Базис_16/Базис_6 -> 0.93870859 | O20: =Базис_26/Базис_16 -> 0.98262427 | P20: =Базис_36/Базис_26 -> 1.0686355 | R20: Ошская область | T20: =Базис_Ж_16/Базис_Ж_6 -> 0.98251256 | U20: =Базис_Ж_26/Базис_Ж_16 -> 1.0488953 | V20: =Базис_Ж_36/Базис_Ж_26 -> 1.0524673 | W20: =Базис_Ж_46/Базис_Ж_36 -> 1.3901038 | X20: =Базис_Ж_56/Базис_Ж_46 -> 1.1521131 | Y20: =Базис_Ж_66/Базис_Ж_56 -> 1.01215 | Z20: =Базис_Ж_76/Базис_Ж_66 -> 0.92477421 | AA20: =Базис_Ж_86/Базис_Ж_76 -> 0.88589442 | AB20: =Базис_Ж_96/Базис_Ж_86 -> 0.93622663 | AC20: =Базис_Ж_106/Базис_Ж_96 -> 0.84975406 | AD20: =AD8/Базис_Ж_106 -> 0.85739344 | AE20: =AE8/AD8 -> 1.3565876 | AF20: =AF8/AE8 -> 1.3191072 | AH20: Ошская область | AJ20: =Базис_М_16/Базис_М_6 -> 0.90721202 | AK20: =Базис_М_26/Базис_М_16 -> 0.931018 | AL20: =Базис_М_36/Базис_М_26 -> 1.08282 | AM20: =Базис_М_46/Базис_М_36 -> 1.2741783 | AN20: =Базис_М_56/Базис_М_46 -> 1.3440407 | AO20: =Базис_М_66/Базис_М_56 -> 1.0362646 | AP20: =Базис_М_76/Базис_М_66 -> 1.0111309 | AQ20: =Базис_М_86/Базис_М_76 -> 0.91501541 | AR20: =Базис_М_96/Базис_М_86 -> 0.93041386 | AS20: =Базис_М_106/Базис_М_96 -> 0.85952209 | AT20: =AT8/Базис_М_106 -> 0.70333373 | AU20: =AU8/AT8 -> 1.4812239 | AV20: =AV8/AU8 -> 1.3117655
B21: Таласская область | D21: =Базис_17/Базис_7 -> 1.0049188 | E21: =Базис_27/Базис_17 -> 1.1199217 | F21: =Базис_37/Базис_27 -> 0.9965035 | G21: =Базис_47/Базис_37 -> 1.2381579 | H21: =Базис_57/Базис_47 -> 1.0694297 | I21: =Базис_67/Базис_57 -> 1.0102683 | J21: =Базис_77/Базис_67 -> 1.0213115 | K21: =Базис_87/Базис_77 -> 1.0224719 | L21: =Базис_97/Базис_87 -> 1.0279435 | M21: =Базис_107/Базис_97 -> 0.80543677 | N21: =Базис_17/Базис_7 -> 1.0049188 | O21: =Базис_27/Базис_17 -> 1.1199217 | P21: =Базис_37/Базис_27 -> 0.9965035 | R21: Таласская область | T21: =Базис_Ж_17/Базис_Ж_7 -> 1.0989625 | U21: =Базис_Ж_27/Базис_Ж_17 -> 1.0965868 | V21: =Базис_Ж_37/Базис_Ж_27 -> 1.0298013 | W21: =Базис_Ж_47/Базис_Ж_37 -> 1.1446945 | X21: =Базис_Ж_57/Базис_Ж_47 -> 1.0157303 | Y21: =Базис_Ж_67/Базис_Ж_57 -> 0.92920354 | Z21: =Базис_Ж_77/Базис_Ж_67 -> 0.94940476 | AA21: =Базис_Ж_87/Базис_Ж_77 -> 0.97617555 | AB21: =Базис_Ж_97/Базис_Ж_87 -> 1.032113 | AC21: =Базис_Ж_107/Базис_Ж_97 -> 0.80211574 | AD21: =AD9/Базис_Ж_107 -> 0.97207137 | AE21: =AE9/AD9 -> 1.2342016 | AF21: =AF9/AE9 -> 1.1691259 | AH21: Таласская область | AJ21: =Базис_М_17/Базис_М_7 -> 0.85384615 | AK21: =Базис_М_27/Базис_М_17 -> 1.1681682 | AL21: =Базис_М_37/Базис_М_27 -> 0.93187661 | AM21: =Базис_М_47/Базис_М_37 -> 1.4386207 | AN21: =Базис_М_57/Базис_М_47 -> 1.1610738 | AO21: =Базис_М_67/Базис_М_57 -> 1.1312964 | AP21: =Базис_М_77/Базис_М_67 -> 1.1094891 | AQ21: =Базис_М_87/Базис_М_77 -> 1.0710526 | AR21: =Базис_М_97/Базис_М_87 -> 1.0239558 | AS21: =Базис_М_107/Базис_М_97 -> 0.80863827 | AT21: =AT9/Базис_М_107 -> 0.49406528 | AU21: =AU9/AT9 -> 1.7384657 | AV21: =AV9/AU9 -> 1.439777
B22: Чуйская область | D22: =Базис_18/Базис_8 -> 0.95803943 | E22: =Базис_28/Базис_18 -> 0.96545214 | F22: =Базис_38/Базис_28 -> 0.95111459 | G22: =Базис_48/Базис_38 -> 0.90460526 | H22: =Базис_58/Базис_48 -> 0.94431818 | I22: =Базис_68/Базис_58 -> 1.1622142 | J22: =Базис_78/Базис_68 -> 1.1215573 | K22: =Базис_88/Базис_78 -> 0.95180945 | L22: =Базис_98/Базис_88 -> 0.70979631 | M22: =Базис_108/Базис_98 -> 0.60043728 | N22: =Базис_18/Базис_8 -> 0.95803943 | O22: =Базис_28/Базис_18 -> 0.96545214 | P22: =Базис_38/Базис_28 -> 0.95111459 | R22: Чуйская область | T22: =Базис_Ж_18/Базис_Ж_8 -> 0.93704459 | U22: =Базис_Ж_28/Базис_Ж_18 -> 0.92752722 | V22: =Базис_Ж_38/Базис_Ж_28 -> 0.96646546 | W22: =Базис_Ж_48/Базис_Ж_38 -> 0.89417071 | X22: =Базис_Ж_58/Базис_Ж_48 -> 0.86961583 | Y22: =Базис_Ж_68/Базис_Ж_58 -> 1.1472557 | Z22: =Базис_Ж_78/Базис_Ж_68 -> 1.0972384 | AA22: =Базис_Ж_88/Базис_Ж_78 -> 0.91563275 | AB22: =Базис_Ж_98/Базис_Ж_88 -> 0.75764615 | AC22: =Базис_Ж_108/Базис_Ж_98 -> 0.66581502 | AD22: =AD10/Базис_Ж_108 -> 1 | AE22: =AE10/AD10 -> 1.9928138 | AF22: =AF10/AE10 -> 1.3213248 | AH22: Чуйская область | AJ22: =Базис_М_18/Базис_М_8 -> 0.99237369 | AK22: =Базис_М_28/Базис_М_18 -> 1.0240154 | AL22: =Базис_М_38/Базис_М_28 -> 0.92964353 | AM22: =Базис_М_48/Базис_М_38 -> 0.919778 | AN22: =Базис_М_58/Базис_М_48 -> 1.0499177 | AO22: =Базис_М_68/Базис_М_58 -> 1.1797283 | AP22: =Базис_М_78/Базис_М_68 -> 1.1492471 | AQ22: =Базис_М_88/Базис_М_78 -> 0.9911368 | AR22: =Базис_М_98/Базис_М_88 -> 0.66174184 | AS22: =Базис_М_108/Базис_М_98 -> 0.52526439 | AT22: =AT10/Базис_М_108 -> 1 | AU22: =AU10/AT10 -> 2.2424242 | AV22: =AV10/AU10 -> 1.2944404
B23: г.Бишкек | D23: =Базис_19/Базис_9 -> 0.94231821 | E23: =Базис_29/Базис_19 -> 0.8597331 | F23: =Базис_39/Базис_29 -> 0.85675721 | G23: =Базис_49/Базис_39 -> 0.99625837 | H23: =Базис_59/Базис_49 -> 1.1737498 | I23: =Базис_69/Базис_59 -> 0.99898956 | J23: =Базис_79/Базис_69 -> 1.0121376 | K23: =Базис_89/Базис_79 -> 1.0448035 | L23: =Базис_99/Базис_89 -> 0.8496732 | M23: =Базис_109/Базис_99 -> 0.80863039 | N23: =Базис_19/Базис_9 -> 0.94231821 | O23: =Базис_29/Базис_19 -> 0.8597331 | P23: =Базис_39/Базис_29 -> 0.85675721 | R23: г.Бишкек | T23: =Базис_Ж_19/Базис_Ж_9 -> 0.97192316 | U23: =Базис_Ж_29/Базис_Ж_19 -> 0.84926151 | V23: =Базис_Ж_39/Базис_Ж_29 -> 0.87033248 | W23: =Базис_Ж_49/Базис_Ж_39 -> 0.99794299 | X23: =Базис_Ж_59/Базис_Ж_49 -> 1.1310365 | Y23: =Базис_Ж_69/Базис_Ж_59 -> 0.99661546 | Z23: =Базис_Ж_79/Базис_Ж_69 -> 0.96734587 | AA23: =Базис_Ж_89/Базис_Ж_79 -> 1.0518499 | AB23: =Базис_Ж_99/Базис_Ж_89 -> 0.85750963 | AC23: =Базис_Ж_109/Базис_Ж_99 -> 0.8257485 | AD23: =AD11/Базис_Ж_109 -> 1 | AE23: =AE11/AD11 -> 1.3651197 | AF23: =AF11/AE11 -> 1.2581673 | AH23: г.Бишкек | AJ23: =Базис_М_19/Базис_М_9 -> 0.88794106 | AK23: =Базис_М_29/Базис_М_19 -> 0.88078603 | AL23: =Базис_М_39/Базис_М_29 -> 0.83044125 | AM23: =Базис_М_49/Базис_М_39 -> 0.99283582 | AN23: =Базис_М_59/Базис_М_49 -> 1.2609741 | AO23: =Базис_М_69/Базис_М_59 -> 1.0033381 | AP23: =Базис_М_79/Базис_М_69 -> 1.0936312 | AQ23: =Базис_М_89/Базис_М_79 -> 1.0334637 | AR23: =Базис_М_99/Базис_М_89 -> 0.83683768 | AS23: =Базис_М_109/Базис_М_99 -> 0.7798995 | AT23: =AT11/Базис_М_109 -> 1 | AU23: =AU11/AT11 -> 1.3264995 | AV23: =AV11/AU11 -> 1.2527157
B24: г.Ош | D24: =Базис_20/Базис_10 -> 1.1127785 | E24: =Базис_30/Базис_20 -> 0.9865141 | F24: =Базис_40/Базис_30 -> 0.94034797 | G24: =Базис_50/Базис_40 -> 1.0255507 | H24: =Базис_60/Базис_50 -> 1.1439003 | I24: =Базис_70/Базис_60 -> 1.160721 | J24: =Базис_80/Базис_70 -> 1.0857328 | K24: =Базис_90/Базис_80 -> 0.91328963 | L24: =Базис_100/Базис_90 -> 0.95530179 | M24: =Базис_110/Базис_100 -> 1.0088798 | N24: =Базис_20/Базис_10 -> 1.1127785 | O24: =Базис_30/Базис_20 -> 0.9865141 | P24: =Базис_40/Базис_30 -> 0.94034797 | R24: г. Ош | T24: =Базис_Ж_20/Базис_Ж_10 -> 1.129285 | U24: =Базис_Ж_30/Базис_Ж_20 -> 1.0112749 | V24: =Базис_Ж_40/Базис_Ж_30 -> 0.93653516 | W24: =Базис_Ж_50/Базис_Ж_40 -> 1.0741758 | X24: =Базис_Ж_60/Базис_Ж_50 -> 1.3103154 | Y24: =Базис_Ж_70/Базис_Ж_60 -> 1.0969421 | Z24: =Базис_Ж_80/Базис_Ж_70 -> 0.9940688 | AA24: =Базис_Ж_90/Базис_Ж_80 -> 0.86933174 | AB24: =Базис_Ж_100/Базис_Ж_90 -> 0.98284146 | AC24: =Базис_Ж_110/Базис_Ж_100 -> 1.1166201 | AD24: =AD12/Базис_Ж_110 -> 0.63852408 | AE24: =AE12/AD12 -> 1.3348767 | AF24: =AF12/AE12 -> 1.2370598 | AH24: г. Ош | AJ24: =Базис_М_20/Базис_М_10 -> 1.098472 | AK24: =Базис_М_30/Базис_М_20 -> 0.96445131 | AL24: =Базис_М_40/Базис_М_30 -> 0.94391026 | AM24: =Базис_М_50/Базис_М_40 -> 0.98047538 | AN24: =Базис_М_60/Базис_М_50 -> 0.97489177 | AO24: =Базис_М_70/Базис_М_60 -> 1.2477798 | AP24: =Базис_М_80/Базис_М_70 -> 1.1957295 | AQ24: =Базис_М_90/Базис_М_80 -> 0.95714286 | AR24: =Базис_М_100/Базис_М_90 -> 0.93034826 | AS24: =Базис_М_110/Базис_М_100 -> 0.90574866 | AT24: =AT12/Базис_М_110 -> 0.83099631 | AU24: =AU12/AT12 -> 1.1886808 | AV24: =AV12/AU12 -> 1.255179
B26: Темп роста базисный | R26: Темп роста базисный | AH26: Темп роста базисный
B27: Кыргызская Республика | D27: =Базис_11/Базис_1 -> 0.9616111 | E27: =Базис_21/Базис_1 -> 0.95421145 | F27: =Базис_31/Базис_1 -> 0.9885314 | G27: =Базис_41/Базис_1 -> 1.2167187 | H27: =Базис_51/Базис_1 -> 1.3065447 | I27: =Базис_61/Базис_1 -> 1.3160045 | J27: =Базис_71/Базис_1 -> 1.3042956 | K27: =Базис_81/Базис_1 -> 1.2821996 | L27: =Базис_91/Базис_1 -> 1.1606462 | M27: =Базис_101/Базис_1 -> 0.87309 | N27: =N3/Базис_1 -> 0.87309 | O27: =O3/Базис_1 -> 1.1239867 | P27: =P3/Базис_1 -> 1.3160045 | R27: Кыргызская Республика | T27: =Базис_Ж_11/Базис_Ж_1 -> 0.98077811 | U27: =Базис_Ж_21/Базис_Ж_1 -> 0.97174415 | V27: =Базис_Ж_31/Базис_Ж_1 -> 0.96544675 | W27: =Базис_Ж_41/Базис_Ж_1 -> 1.1658094 | X27: =Базис_Ж_51/Базис_Ж_1 -> 1.2139466 | Y27: =Базис_Ж_61/Базис_Ж_1 -> 1.1837784 | Z27: =Базис_Ж_71/Базис_Ж_1 -> 1.1309594 | AA27: =Базис_Ж_81/Базис_Ж_1 -> 1.0905704 | AB27: =Базис_Ж_91/Базис_Ж_1 -> 0.98245961 | AC27: =Базис_Ж_101/Базис_Ж_1 -> 0.75759974 | AD27: =AD3/Базис_Ж_1 -> 0.75759974 | AE27: =AE3/Базис_Ж_1 -> 1.0402811 | AF27: =AF3/Базис_Ж_1 -> 1.2139466 | AH27: Кыргызская Республика | AJ27: =Базис_М_11/Базис_М_1 -> 0.94078665 | AK27: =Базис_М_21/Базис_М_1 -> 0.93516263 | AL27: =Базис_М_31/Базис_М_1 -> 1.0136123 | AM27: =Базис_М_41/Базис_М_1 -> 1.2720304 | AN27: =Базис_М_51/Базис_М_1 -> 1.40715 | AO27: =Базис_М_61/Базис_М_1 -> 1.4596647 | AP27: =Базис_М_71/Базис_М_1 -> 1.4926207 | AQ27: =Базис_М_81/Базис_М_1 -> 1.4903998 | AR27: =Базис_М_91/Базис_М_1 -> 1.3542413 | AS27: =Базис_М_101/Базис_М_1 -> 0.99856713 | AT27: =AT3/Базис_М_1 -> 0.93516263 | AU27: =AU3/Базис_М_1 -> 1.2149305 | AV27: =AV3/Базис_М_1 -> 1.4926207
B28: Баткенская область | D28: =Базис_12/Базис_2 -> 0.97766749 | E28: =Базис_22/Базис_2 -> 0.82514475 | F28: =Базис_32/Базис_2 -> 1.0367246 | G28: =Базис_42/Базис_2 -> 1.4812242 | H28: =Базис_52/Базис_2 -> 1.8074442 | I28: =Базис_62/Базис_2 -> 1.6459884 | J28: =Базис_72/Базис_2 -> 1.638048 | K28: =Базис_82/Базис_2 -> 2.2315964 | L28: =Базис_92/Базис_2 -> 2.3291977 | M28: =Базис_102/Базис_2 -> 1.41555 | N28: =N4/Базис_2 -> 0.82514475 | O28: =O4/Базис_2 -> 1.4898714 | P28: =P4/Базис_2 -> 2.3291977 | R28: Баткенская область | T28: =Базис_Ж_12/Базис_Ж_2 -> 1.0639618 | U28: =Базис_Ж_22/Базис_Ж_2 -> 0.87589499 | V28: =Базис_Ж_32/Базис_Ж_2 -> 0.96610979 | W28: =Базис_Ж_42/Базис_Ж_2 -> 1.7217184 | X28: =Базис_Ж_52/Базис_Ж_2 -> 2.4529833 | Y28: =Базис_Ж_62/Базис_Ж_2 -> 2.1484487 | Z28: =Базис_Ж_72/Базис_Ж_2 -> 2.0272076 | AA28: =Базис_Ж_82/Базис_Ж_2 -> 2.6596659 | AB28: =Базис_Ж_92/Базис_Ж_2 -> 2.7847255 | AC28: =Базис_Ж_102/Базис_Ж_2 -> 1.6668258 | AD28: =AD4/Базис_Ж_2 -> 0.87589499 | AE28: =AE4/Базис_Ж_2 -> 1.7606856 | AF28: =AF4/Базис_Ж_2 -> 2.7847255 | AH28: Баткенская область | AJ28: =Базис_М_12/Базис_М_2 -> 0.93189873 | AK28: =Базис_М_22/Базис_М_2 -> 0.79822785 | AL28: =Базис_М_32/Базис_М_2 -> 1.0741772 | AM28: =Базис_М_42/Базис_М_2 -> 1.3536709 | AN28: =Базис_М_52/Базис_М_2 -> 1.4650633 | AO28: =Базис_М_62/Базис_М_2 -> 1.3794937 | AP28: =Базис_М_72/Базис_М_2 -> 1.4316456 | AQ28: =Базис_М_82/Базис_М_2 -> 2.004557 | AR28: =Базис_М_92/Базис_М_2 -> 2.0875949 | AS28: =Базис_М_102/Базис_М_2 -> 1.2822785 | AT28: =AT4/Базис_М_2 -> 0.79822785 | AU28: =AU4/Базис_М_2 -> 1.3462371 | AV28: =AV4/Базис_М_2 -> 2.0875949
B29: Джалал-Абадская область | D29: =Базис_13/Базис_3 -> 0.96226857 | E29: =Базис_23/Базис_3 -> 1.0760878 | F29: =Базис_33/Базис_3 -> 1.3132568 | G29: =Базис_43/Базис_3 -> 1.8335286 | H29: =Базис_53/Базис_3 -> 1.7750957 | I29: =Базис_63/Базис_3 -> 1.7560347 | J29: =Базис_73/Базис_3 -> 1.6960394 | K29: =Базис_83/Базис_3 -> 1.5423795 | L29: =Базис_93/Базис_3 -> 1.3450512 | M29: =Базис_103/Базис_3 -> 0.96742442 | N29: =N5/Базис_3 -> 0.96226857 | O29: =O5/Базис_3 -> 1.3879242 | P29: =P5/Базис_3 -> 1.8335286 | R29: Джалал-Абадская область | T29: =Базис_Ж_13/Базис_Ж_3 -> 0.94996535 | U29: =Базис_Ж_23/Базис_Ж_3 -> 1.0162162 | V29: =Базис_Ж_33/Базис_Ж_3 -> 1.1135135 | W29: =Базис_Ж_43/Базис_Ж_3 -> 1.5021483 | X29: =Базис_Ж_53/Базис_Ж_3 -> 1.3700624 | Y29: =Базис_Ж_63/Базис_Ж_3 -> 1.2644491 | Z29: =Базис_Ж_73/Базис_Ж_3 -> 1.1786556 | AA29: =Базис_Ж_83/Базис_Ж_3 -> 1.0595981 | AB29: =Базис_Ж_93/Базис_Ж_3 -> 0.88454608 | AC29: =Базис_Ж_103/Базис_Ж_3 -> 0.67428967 | AD29: =AD5/Базис_Ж_3 -> 0.67428967 | AE29: =AE5/Базис_Ж_3 -> 1.0921313 | AF29: =AF5/Базис_Ж_3 -> 1.5021483 | AH29: Джалал-Абадская область | AJ29: =Базис_М_13/Базис_М_3 -> 0.97815968 | AK29: =Базис_М_23/Базис_М_3 -> 1.1534193 | AL29: =Базис_М_33/Базис_М_3 -> 1.5712496 | AM29: =Базис_М_43/Базис_М_3 -> 2.2615467 | AN29: =Базис_М_53/Базис_М_3 -> 2.2982456 | AO29: =Базис_М_63/Базис_М_3 -> 2.3909774 | AP29: =Базис_М_73/Базис_М_3 -> 2.3643036 | AQ29: =Базис_М_83/Базис_М_3 -> 2.1659506 | AR29: =Базис_М_93/Базис_М_3 -> 1.9398496 | AS29: =Базис_М_103/Базис_М_3 -> 1.3460437 | AT29: =AT5/Базис_М_3 -> 0.97815968 | AU29: =AU5/Базис_М_3 -> 1.7699769 | AV29: =AV5/Базис_М_3 -> 2.3909774
B30: Иссык-Кульская область | D30: =Базис_14/Базис_4 -> 1.0534922 | E30: =Базис_24/Базис_4 -> 1.0885307 | F30: =Базис_34/Базис_4 -> 0.98037842 | G30: =Базис_44/Базис_4 -> 0.98154637 | H30: =Базис_54/Базис_4 -> 1.00911 | I30: =Базис_64/Базис_4 -> 1.049054 | J30: =Базис_74/Базис_4 -> 0.99065639 | K30: =Базис_84/Базис_4 -> 0.87199253 | L30: =Базис_94/Базис_4 -> 0.64494277 | M30: =Базис_104/Базис_4 -> 0.52441018 | N30: =N6/Базис_4 -> 0.52441018 | O30: =O6/Базис_4 -> 0.92673759 | P30: =P6/Базис_4 -> 1.0885307 | R30: Иссык-Кульская область | T30: =Базис_Ж_14/Базис_Ж_4 -> 1.0228086 | U30: =Базис_Ж_24/Базис_Ж_4 -> 1.068873 | V30: =Базис_Ж_34/Базис_Ж_4 -> 1.0496422 | W30: =Базис_Ж_44/Базис_Ж_4 -> 1.0308587 | X30: =Базис_Ж_54/Базис_Ж_4 -> 1.0313059 | Y30: =Базис_Ж_64/Базис_Ж_4 -> 1.0581395 | Z30: =Базис_Ж_74/Базис_Ж_4 -> 1.0205725 | AA30: =Базис_Ж_84/Базис_Ж_4 -> 0.88237925 | AB30: =Базис_Ж_94/Базис_Ж_4 -> 0.68962433 | AC30: =Базис_Ж_104/Базис_Ж_4 -> 0.52683363 | AD30: =AD6/Базис_Ж_4 -> 0.52683363 | AE30: =AE6/Базис_Ж_4 -> 0.94373069 | AF30: =AF6/Базис_Ж_4 -> 1.068873 | AH30: Иссык-Кульская область | AJ30: =Базис_М_14/Базис_М_4 -> 1.0870416 | AK30: =Базис_М_24/Базис_М_4 -> 1.1100244 | AL30: =Базис_М_34/Базис_М_4 -> 0.90464548 | AM30: =Базис_М_44/Базис_М_4 -> 0.92762836 | AN30: =Базис_М_54/Базис_М_4 -> 0.98484108 | AO30: =Базис_М_64/Базис_М_4 -> 1.0391198 | AP30: =Базис_М_74/Базис_М_4 -> 0.95794621 | AQ30: =Базис_М_84/Базис_М_4 -> 0.8606357 | AR30: =Базис_М_94/Базис_М_4 -> 0.59608802 | AS30: =Базис_М_104/Базис_М_4 -> 0.52176039 | AT30: =AT6/Базис_М_4 -> 0.52176039 | AU30: =AU6/Базис_М_4 -> 0.90815737 | AV30: =AV6/Базис_М_4 -> 1.1100244
B31: Нарынская Область | D31: =Базис_15/Базис_5 -> 0.88256344 | E31: =Базис_25/Базис_5 -> 0.88516591 | F31: =Базис_35/Базис_5 -> 0.66476903 | G31: =Базис_45/Базис_5 -> 0.66167859 | H31: =Базис_55/Базис_5 -> 0.46811971 | I31: =Базис_65/Базис_5 -> 0.46405335 | J31: =Базис_75/Базис_5 -> 0.45234223 | K31: =Базис_85/Базис_5 -> 0.40370852 | L31: =Базис_95/Базис_5 -> 0.32156799 | M31: =Базис_105/Базис_5 -> 0.25374105 | N31: =N7/Базис_5 -> 0.25374105 | O31: =O7/Базис_5 -> 0.58706453 | P31: =P7/Базис_5 -> 1 | R31: Нарынская область | T31: =Базис_Ж_15/Базис_Ж_5 -> 0.93258093 | U31: =Базис_Ж_25/Базис_Ж_5 -> 0.95663796 | V31: =Базис_Ж_35/Базис_Ж_5 -> 0.75705376 | W31: =Базис_Ж_45/Базис_Ж_5 -> 0.64805465 | X31: =Базис_Ж_55/Базис_Ж_5 -> 0.42174042 | Y31: =Базис_Ж_65/Базис_Ж_5 -> 0.41639442 | Z31: =Базис_Ж_75/Базис_Ж_5 -> 0.41134541 | AA31: =Базис_Ж_85/Базис_Ж_5 -> 0.36501337 | AB31: =Базис_Ж_95/Базис_Ж_5 -> 0.2955153 | AC31: =Базис_Ж_105/Базис_Ж_5 -> 0.23552124 | AD31: =AD7/Базис_Ж_5 -> 0.23552124 | AE31: =AE7/Базис_Ж_5 -> 0.58544159 | AF31: =AF7/Базис_Ж_5 -> 1 | AH31: Нарынская область | AJ31: =Базис_М_15/Базис_М_5 -> 0.82200647 | AK31: =Базис_М_25/Базис_М_5 -> 0.79863359 | AL31: =Базис_М_35/Базис_М_5 -> 0.55303848 | AM31: =Базис_М_45/Базис_М_5 -> 0.67817332 | AN31: =Базис_М_55/Базис_М_5 -> 0.52427184 | AO31: =Базис_М_65/Базис_М_5 -> 0.52175476 | AP31: =Базис_М_75/Базис_М_5 -> 0.50197771 | AQ31: =Базис_М_85/Базис_М_5 -> 0.45055735 | AR31: =Базис_М_95/Базис_М_5 -> 0.35311039 | AS31: =Базис_М_105/Базис_М_5 -> 0.27580007 | AT31: =AT7/Базис_М_5 -> 0.27580007 | AU31: =AU7/Базис_М_5 -> 0.58902945 | AV31: =AV7/Базис_М_5 -> 1
B32: Ошская область | D32: =Базис_16/Базис_6 -> 0.93870859 | E32: =Базис_26/Базис_6 -> 0.92239785 | F32: =Базис_36/Базис_6 -> 0.98570708 | G32: =Базис_46/Базис_6 -> 1.3085589 | H32: =Базис_56/Базис_6 -> 1.6377165 | I32: =Базис_66/Базис_6 -> 1.6795863 | J32: =Базис_76/Базис_6 -> 1.6347738 | K32: =Базис_86/Базис_6 -> 1.4760383 | L32: =Базис_96/Базис_6 -> 1.3768287 | M32: =Базис_106/Базис_6 -> 1.1779048 | N32: =N8/Базис_6 -> 0.92239785 | O32: =O8/Базис_6 -> 1.2852928 | P32: =P8/Базис_6 -> 1.6795863 | R32: Ошская область | T32: =Базис_Ж_16/Базис_Ж_6 -> 0.98251256 | U32: =Базис_Ж_26/Базис_Ж_6 -> 1.0305528 | V32: =Базис_Ж_36/Базис_Ж_6 -> 1.0846231 | W32: =Базис_Ж_46/Базис_Ж_6 -> 1.5077387 | X32: =Базис_Ж_56/Базис_Ж_6 -> 1.7370854 | Y32: =Базис_Ж_66/Базис_Ж_6 -> 1.758191 | Z32: =Базис_Ж_76/Базис_Ж_6 -> 1.6259296 | AA32: =Базис_Ж_86/Базис_Ж_6 -> 1.440402 | AB32: =Базис_Ж_96/Базис_Ж_6 -> 1.3485427 | AC32: =Базис_Ж_106/Базис_Ж_6 -> 1.1459296 | AD32: =AD8/Базис_Ж_6 -> 0.98251256 | AE32: =AE8/Базис_Ж_6 -> 1.3328643 | AF32: =AF8/Базис_Ж_6 -> 1.758191 | AH32: Ошская область | AJ32: =Базис_М_16/Базис_М_6 -> 0.90721202 | AK32: =Базис_М_26/Базис_М_6 -> 0.84463073 | AL32: =Базис_М_36/Базис_М_6 -> 0.91458303 | AM32: =Базис_М_46/Базис_М_6 -> 1.1653418 | AN32: =Базис_М_56/Базис_М_6 -> 1.5662668 | AO32: =Базис_М_66/Базис_М_6 -> 1.6230669 | AP32: =Базис_М_76/Базис_М_6 -> 1.6411331 | AQ32: =Базис_М_86/Базис_М_6 -> 1.5016621 | AR32: =Базис_М_96/Базис_М_6 -> 1.3971672 | AS32: =Базис_М_106/Базис_М_6 -> 1.2008961 | AT32: =AT8/Базис_М_6 -> 0.84463073 | AU32: =AU8/Базис_М_6 -> 1.2510873 | AV32: =AV8/Базис_М_6 -> 1.6411331
B33: Таласская область | D33: =Базис_17/Базис_7 -> 1.0049188 | E33: =Базис_27/Базис_7 -> 1.1254304 | F33: =Базис_37/Базис_7 -> 1.1214953 | G33: =Базис_47/Базис_7 -> 1.3885883 | H33: =Базис_57/Базис_7 -> 1.4849975 | I33: =Базис_67/Базис_7 -> 1.5002459 | J33: =Базис_77/Базис_7 -> 1.5322184 | K33: =Базис_87/Базис_7 -> 1.5666503 | L33: =Базис_97/Базис_7 -> 1.6104279 | M33: =Базис_107/Базис_7 -> 1.2970979 | N33: =N9/Базис_7 -> 1 | O33: =O9/Базис_7 -> 1.3301883 | P33: =P9/Базис_7 -> 1.6104279 | R33: Таласская область | T33: =Базис_Ж_17/Базис_Ж_7 -> 1.0989625 | U33: =Базис_Ж_27/Базис_Ж_7 -> 1.2051077 | V33: =Базис_Ж_37/Базис_Ж_7 -> 1.2410215 | W33: =Базис_Ж_47/Базис_Ж_7 -> 1.4205906 | X33: =Базис_Ж_57/Базис_Ж_7 -> 1.442937 | Y33: =Базис_Ж_67/Базис_Ж_7 -> 1.3407821 | Z33: =Базис_Ж_77/Базис_Ж_7 -> 1.2729449 | AA33: =Базис_Ж_87/Базис_Ж_7 -> 1.2426177 | AB33: =Базис_Ж_97/Базис_Ж_7 -> 1.2825219 | AC33: =Базис_Ж_107/Базис_Ж_7 -> 1.028731 | AD33: =AD9/Базис_Ж_7 -> 1 | AE33: =AE9/Базис_Ж_7 -> 1.2342016 | AF33: =AF9/Базис_Ж_7 -> 1.442937 | AH33: Таласская область | AJ33: =Базис_М_17/Базис_М_7 -> 0.85384615 | AK33: =Базис_М_27/Базис_М_7 -> 0.9974359 | AL33: =Базис_М_37/Базис_М_7 -> 0.92948718 | AM33: =Базис_М_47/Базис_М_7 -> 1.3371795 | AN33: =Базис_М_57/Базис_М_7 -> 1.5525641 | AO33: =Базис_М_67/Базис_М_7 -> 1.7564103 | AP33: =Базис_М_77/Базис_М_7 -> 1.9487179 | AQ33: =Базис_М_87/Базис_М_7 -> 2.0871795 | AR33: =Базис_М_97/Базис_М_7 -> 2.1371795 | AS33: =Базис_М_107/Базис_М_7 -> 1.7282051 | AT33: =AT9/Базис_М_7 -> 0.85384615 | AU33: =AU9/Базис_М_7 -> 1.4843823 | AV33: =AV9/Базис_М_7 -> 2.1371795
B34: Чуйская область | D34: =Базис_18/Базис_8 -> 0.95803943 | E34: =Базис_28/Базис_8 -> 0.92494122 | F34: =Базис_38/Базис_8 -> 0.87972509 | G34: =Базис_48/Базис_8 -> 0.79580394 | H34: =Базис_58/Базис_8 -> 0.75149213 | I34: =Базис_68/Базис_8 -> 0.87339483 | J34: =Базис_78/Базис_8 -> 0.97956231 | K34: =Базис_88/Базис_8 -> 0.93235666 | L34: =Базис_98/Базис_8 -> 0.66178332 | M34: =Базис_108/Базис_8 -> 0.39735938 | N34: =N10/Базис_8 -> 0.39735938 | O34: =O10/Базис_8 -> 0.83222348 | P34: =P10/Базис_8 -> 1 | R34: Чуйская область | T34: =Базис_Ж_18/Базис_Ж_8 -> 0.93704459 | U34: =Базис_Ж_28/Базис_Ж_8 -> 0.86913436 | V34: =Базис_Ж_38/Базис_Ж_8 -> 0.83998834 | W34: =Базис_Ж_48/Базис_Ж_8 -> 0.75109298 | X34: =Базис_Ж_58/Базис_Ж_8 -> 0.65316234 | Y34: =Базис_Ж_68/Базис_Ж_8 -> 0.74934421 | Z34: =Базис_Ж_78/Базис_Ж_8 -> 0.82220927 | AA34: =Базис_Ж_88/Базис_Ж_8 -> 0.75284174 | AB34: =Базис_Ж_98/Базис_Ж_8 -> 0.57038764 | AC34: =Базис_Ж_108/Базис_Ж_8 -> 0.37977266 | AD34: =AD10/Базис_Ж_8 -> 0.37977266 | AE34: =AE10/Базис_Ж_8 -> 0.75681619 | AF34: =AF10/Базис_Ж_8 -> 1 | AH34: Чуйская область | AJ34: =Базис_М_18/Базис_М_8 -> 0.99237369 | AK34: =Базис_М_28/Базис_М_8 -> 1.0162059 | AL34: =Базис_М_38/Базис_М_8 -> 0.94470925 | AM34: =Базис_М_48/Базис_М_8 -> 0.86892278 | AN34: =Базис_М_58/Базис_М_8 -> 0.91229743 | AO34: =Базис_М_68/Базис_М_8 -> 1.0762631 | AP34: =Базис_М_78/Базис_М_8 -> 1.2368923 | AQ34: =Базис_М_88/Базис_М_8 -> 1.2259295 | AR34: =Базис_М_98/Базис_М_8 -> 0.81124881 | AS34: =Базис_М_108/Базис_М_8 -> 0.42612011 | AT34: =AT10/Базис_М_8 -> 0.42612011 | AU34: =AU10/Базис_М_8 -> 0.95554207 | AV34: =AV10/Базис_М_8 -> 1.2368923
B35: г.Бишкек | D35: =Базис_19/Базис_9 -> 0.94231821 | E35: =Базис_29/Базис_9 -> 0.81014215 | F35: =Базис_39/Базис_9 -> 0.69409513 | G35: =Базис_49/Базис_9 -> 0.69149809 | H35: =Базис_59/Базис_9 -> 0.81164571 | I35: =Базис_69/Базис_9 -> 0.81082559 | J35: =Базис_79/Базис_9 -> 0.82066703 | K35: =Базис_89/Базис_9 -> 0.85743576 | L35: =Базис_99/Базис_9 -> 0.72854019 | M35: =Базис_109/Базис_9 -> 0.58911974 | N35: =N11/Базис_9 -> 0.58911974 | O35: =O11/Базис_9 -> 0.79602614 | P35: =P11/Базис_9 -> 1 | R35: г.Бишкек | T35: =Базис_Ж_19/Базис_Ж_9 -> 0.97192316 | U35: =Базис_Ж_29/Базис_Ж_9 -> 0.82541693 | V35: =Базис_Ж_39/Базис_Ж_9 -> 0.71838716 | W35: =Базис_Ж_49/Базис_Ж_9 -> 0.71690944 | X35: =Базис_Ж_59/Базис_Ж_9 -> 0.81085075 | Y35: =Базис_Ж_69/Базис_Ж_9 -> 0.8081064 | Z35: =Базис_Ж_79/Базис_Ж_9 -> 0.78171839 | AA35: =Базис_Ж_89/Базис_Ж_9 -> 0.82225037 | AB35: =Базис_Ж_99/Базис_Ж_9 -> 0.70508761 | AC35: =Базис_Ж_109/Базис_Ж_9 -> 0.58222504 | AD35: =AD11/Базис_Ж_9 -> 0.58222504 | AE35: =AE11/Базис_Ж_9 -> 0.79480684 | AF35: =AF11/Базис_Ж_9 -> 1 | AH35: г.Бишкек | AJ35: =Базис_М_19/Базис_М_9 -> 0.88794106 | AK35: =Базис_М_29/Базис_М_9 -> 0.78208608 | AL35: =Базис_М_39/Базис_М_9 -> 0.64947654 | AM35: =Базис_М_49/Базис_М_9 -> 0.64482358 | AN35: =Базис_М_59/Базис_М_9 -> 0.81310585 | AO35: =Базис_М_69/Базис_М_9 -> 0.81582009 | AP35: =Базис_М_79/Базис_М_9 -> 0.89220628 | AQ35: =Базис_М_89/Базис_М_9 -> 0.92206282 | AR35: =Базис_М_99/Базис_М_9 -> 0.77161691 | AS35: =Базис_М_109/Базис_М_9 -> 0.60178364 | AT35: =AT11/Базис_М_9 -> 0.60178364 | AU35: =AU11/Базис_М_9 -> 0.79826571 | AV35: =AV11/Базис_М_9 -> 1
B36: г.Ош | D36: =Базис_20/Базис_10 -> 1.1127785 | E36: =Базис_30/Базис_10 -> 1.0977717 | F36: =Базис_40/Базис_10 -> 1.0322874 | G36: =Базис_50/Базис_10 -> 1.058663 | H36: =Базис_60/Базис_10 -> 1.211005 | I36: =Базис_70/Базис_10 -> 1.4056389 | J36: =Базис_80/Базис_10 -> 1.5261482 | K36: =Базис_90/Базис_10 -> 1.3938154 | L36: =Базис_100/Базис_10 -> 1.3315143 | M36: =Базис_110/Базис_10 -> 1.3433379 | N36: =N12/Базис_10 -> 1 | O36: =O12/Базис_10 -> 1.2284509 | P36: =P12/Базис_10 -> 1.5261482 | R36: г. Ош | T36: =Базис_Ж_20/Базис_Ж_10 -> 1.129285 | U36: =Базис_Ж_30/Базис_Ж_10 -> 1.1420176 | V36: =Базис_Ж_40/Базис_Ж_10 -> 1.0695397 | W36: =Базис_Ж_50/Базис_Ж_10 -> 1.1488737 | X36: =Базис_Ж_60/Базис_Ж_10 -> 1.5053869 | Y36: =Базис_Ж_70/Базис_Ж_10 -> 1.6513222 | Z36: =Базис_Ж_80/Базис_Ж_10 -> 1.6415279 | AA36: =Базис_Ж_90/Базис_Ж_10 -> 1.4270323 | AB36: =Базис_Ж_100/Базис_Ж_10 -> 1.4025465 | AC36: =Базис_Ж_110/Базис_Ж_10 -> 1.5661117 | AD36: =AD12/Базис_Ж_10 -> 1 | AE36: =AE12/Базис_Ж_10 -> 1.3348767 | AF36: =AF12/Базис_Ж_10 -> 1.6513222 | AH36: г. Ош | AJ36: =Базис_М_20/Базис_М_10 -> 1.098472 | AK36: =Базис_М_30/Базис_М_10 -> 1.0594228 | AL36: =Базис_М_40/Базис_М_10 -> 1 | AM36: =Базис_М_50/Базис_М_10 -> 0.98047538 | AN36: =Базис_М_60/Базис_М_10 -> 0.95585739 | AO36: =Базис_М_70/Базис_М_10 -> 1.1926995 | AP36: =Базис_М_80/Базис_М_10 -> 1.426146 | AQ36: =Базис_М_90/Базис_М_10 -> 1.3650255 | AR36: =Базис_М_100/Базис_М_10 -> 1.2699491 | AS36: =Базис_М_110/Базис_М_10 -> 1.1502547 | AT36: =AT12/Базис_М_10 -> 0.95585739 | AU36: =AU12/Базис_М_10 -> 1.1362093 | AV36: =AV12/Базис_М_10 -> 1.426146
B38: Темп прироста цепной | R38: Темп прироста цепной | AH38: Темп прироста цепной
B39: Кыргызская Республика | D39: =(Базис_11-Базис_1)/Базис_1 -> -0.038388902 | E39: =(Базис_21-Базис_11)/Базис_11 -> -0.0076950545 | F39: =(Базис_31-Базис_21)/Базис_21 -> 0.035966822 | G39: =(Базис_41-Базис_31)/Базис_31 -> 0.23083469 | H39: =(Базис_51-Базис_41)/Базис_41 -> 0.073826356 | I39: =(Базис_61-Базис_51)/Базис_51 -> 0.0072403779 | J39: =(Базис_71-Базис_61)/Базис_61 -> -0.0088973543 | K39: =(Базис_81-Базис_71)/Базис_71 -> -0.016940898 | L39: =(Базис_91-Базис_81)/Базис_81 -> -0.094800691 | M39: =(Базис_101-Базис_91)/Базис_91 -> -0.24775528 | N39: =(N3-Базис_101)/Базис_101 -> 0 | O39: =(O3-N3)/N3 -> 0.28736633 | P39: =(P3-O3)/O3 -> 0.17083643 | R39: Кыргызская Республика | T39: =(Базис_Ж_11-Базис_Ж_1)/Базис_Ж_1 -> -0.019221893 | U39: =(Базис_Ж_21-Базис_Ж_11)/Базис_Ж_11 -> -0.0092110129 | V39: =(Базис_Ж_31-Базис_Ж_21)/Базис_Ж_21 -> -0.0064805076 | W39: =(Базис_Ж_41-Базис_Ж_31)/Базис_Ж_31 -> 0.20753364 | X39: =(Базис_Ж_51-Базис_Ж_41)/Базис_Ж_41 -> 0.04129076 | Y39: =(Базис_Ж_61-Базис_Ж_51)/Базис_Ж_51 -> -0.0248513 | Z39: =(Базис_Ж_71-Базис_Ж_61)/Базис_Ж_61 -> -0.044618984 | AA39: =(Базис_Ж_81-Базис_Ж_71)/Базис_Ж_71 -> -0.035712203 | AB39: =(Базис_Ж_91-Базис_Ж_81)/Базис_Ж_81 -> -0.099132328 | AC39: =(Базис_Ж_101-Базис_Ж_91)/Базис_Ж_91 -> -0.22887442 | AD39: =(AD3-Базис_Ж_101)/Базис_Ж_101 -> 0 | AE39: =(AE3-AD3)/AD3 -> 0.37312766 | AF39: =(AF3-AE3)/AE3 -> 0.16694087 | AH39: Кыргызская Республика | AJ39: =(Базис_М_11-Базис_М_1)/Базис_М_1 -> -0.059213354 | AK39: =(Базис_М_21-Базис_М_11)/Базис_М_11 -> -0.0059779919 | AL39: =(Базис_М_31-Базис_М_21)/Базис_М_21 -> 0.083888761 | AM39: =(Базис_М_41-Базис_М_31)/Базис_М_31 -> 0.2549477 | AN39: =(Базис_М_51-Базис_М_41)/Базис_М_41 -> 0.1062236 | AO39: =(Базис_М_61-Базис_М_51)/Базис_М_51 -> 0.037319892 | AP39: =(Базис_М_71-Базис_М_61)/Базис_М_61 -> 0.022577795 | AQ39: =(Базис_М_81-Базис_М_71)/Базис_М_71 -> -0.0014879524 | AR39: =(Базис_М_91-Базис_М_81)/Базис_М_81 -> -0.091357016 | AS39: =(Базис_М_101-Базис_М_91)/Базис_М_91 -> -0.26263722 | AT39: =(AT3-Базис_М_101)/Базис_М_101 -> -0.06349548 | AU39: =(AU3-AT3)/AT3 -> 0.29916494 | AV39: =(AV3-AU3)/AU3 -> 0.22856469
B40: Баткенская область | D40: =(Базис_12-Базис_2)/Базис_2 -> -0.022332506 | E40: =(Базис_22-Базис_12)/Базис_12 -> -0.15600677 | F40: =(Базис_32-Базис_22)/Базис_22 -> 0.2564154 | G40: =(Базис_42-Базис_32)/Базис_32 -> 0.42875379 | H40: =(Базис_52-Базис_42)/Базис_42 -> 0.22023677 | I40: =(Базис_62-Базис_52)/Базис_52 -> -0.089328208 | J40: =(Базис_72-Базис_62)/Базис_62 -> -0.0048241206 | K40: =(Базис_82-Базис_72)/Базис_72 -> 0.36235104 | L40: =(Базис_92-Базис_82)/Базис_82 -> 0.043736101 | M40: =(Базис_102-Базис_92)/Базис_92 -> -0.39225852 | N40: =(N4-Базис_102)/Базис_102 -> -0.41708543 | O40: =(O4-N4)/N4 -> 0.80558796 | P40: =(P4-O4)/O4 -> 0.56335483 | R40: Баткенская область | T40: =(Базис_Ж_12-Базис_Ж_2)/Базис_Ж_2 -> 0.063961814 | U40: =(Базис_Ж_22-Базис_Ж_12)/Базис_Ж_12 -> -0.17676088 | V40: =(Базис_Ж_32-Базис_Ж_22)/Базис_Ж_22 -> 0.10299728 | W40: =(Базис_Ж_42-Базис_Ж_32)/Базис_Ж_32 -> 0.78211462 | X40: =(Базис_Ж_52-Базис_Ж_42)/Базис_Ж_42 -> 0.42472969 | Y40: =(Базис_Ж_62-Базис_Ж_52)/Базис_Ж_52 -> -0.12414867 | Z40: =(Базис_Ж_72-Базис_Ж_62)/Базис_Ж_62 -> -0.056431904 | AA40: =(Базис_Ж_82-Базис_Ж_72)/Базис_Ж_72 -> 0.31198493 | AB40: =(Базис_Ж_92-Базис_Ж_82)/Базис_Ж_82 -> 0.047020818 | AC40: =(Базис_Ж_102-Базис_Ж_92)/Базис_Ж_92 -> -0.40143984 | AD40: =(AD4-Базис_Ж_102)/Базис_Ж_102 -> -0.47451317 | AE40: =(AE4-AD4)/AD4 -> 1.0101561 | AF40: =(AF4-AE4)/AE4 -> 0.58161429 | AH40: Баткенская область | AJ40: =(Базис_М_12-Базис_М_2)/Базис_М_2 -> -0.068101266 | AK40: =(Базис_М_22-Базис_М_12)/Базис_М_12 -> -0.14343928 | AL40: =(Базис_М_32-Базис_М_22)/Базис_М_22 -> 0.34570251 | AM40: =(Базис_М_42-Базис_М_32)/Базис_М_32 -> 0.26019326 | AN40: =(Базис_М_52-Базис_М_42)/Базис_М_42 -> 0.082289134 | AO40: =(Базис_М_62-Базис_М_52)/Базис_М_52 -> -0.058406774 | AP40: =(Базис_М_72-Базис_М_62)/Базис_М_62 -> 0.037805102 | AQ40: =(Базис_М_82-Базис_М_72)/Базис_М_72 -> 0.40017683 | AR40: =(Базис_М_92-Базис_М_82)/Базис_М_82 -> 0.041424602 | AS40: =(Базис_М_102-Базис_М_92)/Базис_М_92 -> -0.38576279 | AT40: =(AT4-Базис_М_102)/Базис_М_102 -> -0.3774926 | AU40: =(AU4-AT4)/AT4 -> 0.68653231 | AV40: =(AV4-AU4)/AU4 -> 0.55068896
B41: Джалал-Абадская область | D41: =(Базис_13-Базис_3)/Базис_3 -> -0.037731427 | E41: =(Базис_23-Базис_13)/Базис_13 -> 0.11828219 | F41: =(Базис_33-Базис_23)/Базис_23 -> 0.22039927 | G41: =(Базис_43-Базис_33)/Базис_33 -> 0.39616917 | H41: =(Базис_53-Базис_43)/Базис_43 -> -0.031869115 | I41: =(Базис_63-Базис_53)/Базис_53 -> -0.010738019 | J41: =(Базис_73-Базис_63)/Базис_63 -> -0.034165221 | K41: =(Базис_83-Базис_73)/Базис_73 -> -0.090599235 | L41: =(Базис_93-Базис_83)/Базис_83 -> -0.1279376 | M41: =(Базис_103-Базис_93)/Базис_93 -> -0.2807527 | N41: =(N5-Базис_103)/Базис_103 -> -0.0053294574 | O41: =(O5-N5)/N5 -> 0.44234601 | P41: =(P5-O5)/O5 -> 0.32105815 | R41: Джалал-Абадская область | T41: =(Базис_Ж_13-Базис_Ж_3)/Базис_Ж_3 -> -0.05003465 | U41: =(Базис_Ж_23-Базис_Ж_13)/Базис_Ж_13 -> 0.069740298 | V41: =(Базис_Ж_33-Базис_Ж_23)/Базис_Ж_23 -> 0.095744681 | W41: =(Базис_Ж_43-Базис_Ж_33)/Базис_Ж_33 -> 0.34901668 | X41: =(Базис_Ж_53-Базис_Ж_43)/Базис_Ж_43 -> -0.087931353 | Y41: =(Базис_Ж_63-Базис_Ж_53)/Базис_Ж_53 -> -0.077086495 | Z41: =(Базис_Ж_73-Базис_Ж_63)/Базис_Ж_63 -> -0.067850488 | AA41: =(Базис_Ж_83-Базис_Ж_73)/Базис_Ж_73 -> -0.10101129 | AB41: =(Базис_Ж_93-Базис_Ж_83)/Базис_Ж_83 -> -0.16520602 | AC41: =(Базис_Ж_103-Базис_Ж_93)/Базис_Ж_93 -> -0.23769978 | AD41: =(AD5-Базис_Ж_103)/Базис_Ж_103 -> 0 | AE41: =(AE5-AD5)/AD5 -> 0.61967673 | AF41: =(AF5-AE5)/AE5 -> 0.37542831 | AH41: Джалал-Абадская область | AJ41: =(Базис_М_13-Базис_М_3)/Базис_М_3 -> -0.021840315 | AK41: =(Базис_М_23-Базис_М_13)/Базис_М_13 -> 0.17917277 | AL41: =(Базис_М_33-Базис_М_23)/Базис_М_23 -> 0.36225361 | AM41: =(Базис_М_43-Базис_М_33)/Базис_М_33 -> 0.43933007 | AN41: =(Базис_М_53-Базис_М_43)/Базис_М_43 -> 0.016227341 | AO41: =(Базис_М_63-Базис_М_53)/Базис_М_53 -> 0.040348964 | AP41: =(Базис_М_73-Базис_М_63)/Базис_М_63 -> -0.011156035 | AQ41: =(Базис_М_83-Базис_М_73)/Базис_М_73 -> -0.083894904 | AR41: =(Базис_М_93-Базис_М_83)/Базис_М_83 -> -0.10438879 | AS41: =(Базис_М_103-Базис_М_93)/Базис_М_93 -> -0.30610927 | AT41: =(AT5-Базис_М_103)/Базис_М_103 -> -0.27330762 | AU41: =(AU5-AT5)/AT5 -> 0.80949687 | AV41: =(AV5-AU5)/AU5 -> 0.35085235
B42: Иссык-Кульская область | D42: =(Базис_14-Базис_4)/Базис_4 -> 0.053492175 | E42: =(Базис_24-Базис_14)/Базис_14 -> 0.033259424 | F42: =(Базис_34-Базис_24)/Базис_24 -> -0.099356223 | G42: =(Базис_44-Базис_34)/Базис_34 -> 0.0011913271 | H42: =(Базис_54-Базис_44)/Базис_44 -> 0.028081866 | I42: =(Базис_64-Базис_54)/Базис_54 -> 0.039583333 | J42: =(Базис_74-Базис_64)/Базис_64 -> -0.055666889 | K42: =(Базис_84-Базис_74)/Базис_74 -> -0.11978307 | L42: =(Базис_94-Базис_84)/Базис_84 -> -0.26038039 | M42: =(Базис_104-Базис_94)/Базис_94 -> -0.18688881 | N42: =(N6-Базис_104)/Базис_104 -> 0 | O42: =(O6-N6)/N6 -> 0.76719984 | P42: =(P6-O6)/O6 -> 0.17458353 | R42: Иссык-Кульская область | T42: =(Базис_Ж_14-Базис_Ж_4)/Базис_Ж_4 -> 0.022808587 | U42: =(Базис_Ж_24-Базис_Ж_14)/Базис_Ж_14 -> 0.045037167 | V42: =(Базис_Ж_34-Базис_Ж_24)/Базис_Ж_24 -> -0.017991632 | W42: =(Базис_Ж_44-Базис_Ж_34)/Базис_Ж_34 -> -0.017895185 | X42: =(Базис_Ж_54-Базис_Ж_44)/Базис_Ж_44 -> 0.00043383948 | Y42: =(Базис_Ж_64-Базис_Ж_54)/Базис_Ж_54 -> 0.026019081 | Z42: =(Базис_Ж_74-Базис_Ж_64)/Базис_Ж_64 -> -0.035502959 | AA42: =(Базис_Ж_84-Базис_Ж_74)/Базис_Ж_74 -> -0.13540754 | AB42: =(Базис_Ж_94-Базис_Ж_84)/Базис_Ж_84 -> -0.21844906 | AC42: =(Базис_Ж_104-Базис_Ж_94)/Базис_Ж_94 -> -0.23605707 | AD42: =(AD6-Базис_Ж_104)/Базис_Ж_104 -> 0 | AE42: =(AE6-AD6)/AD6 -> 0.79132582 | AF42: =(AF6-AE6)/AE6 -> 0.13260383 | AH42: Иссык-Кульская область | AJ42: =(Базис_М_14-Базис_М_4)/Базис_М_4 -> 0.087041565 | AK42: =(Базис_М_24-Базис_М_14)/Базис_М_14 -> 0.0211426 | AL42: =(Базис_М_34-Базис_М_24)/Базис_М_24 -> -0.18502203 | AM42: =(Базис_М_44-Базис_М_34)/Базис_М_34 -> 0.025405405 | AN42: =(Базис_М_54-Базис_М_44)/Базис_М_44 -> 0.061676331 | AO42: =(Базис_М_64-Базис_М_54)/Базис_М_54 -> 0.055114201 | AP42: =(Базис_М_74-Базис_М_64)/Базис_М_64 -> -0.078117647 | AQ42: =(Базис_М_84-Базис_М_74)/Базис_М_74 -> -0.10158244 | AR42: =(Базис_М_94-Базис_М_84)/Базис_М_84 -> -0.30738636 | AS42: =(Базис_М_104-Базис_М_94)/Базис_М_94 -> -0.12469237 | AT42: =(AT6-Базис_М_104)/Базис_М_104 -> 0 | AU42: =(AU6-AT6)/AT6 -> 0.74056403 | AV42: =(AV6-AU6)/AU6 -> 0.22228205
B43: Нарынская Область | D43: =(Базис_15-Базис_5)/Базис_5 -> -0.11743656 | E43: =(Базис_25-Базис_15)/Базис_15 -> 0.0029487652 | F43: =(Базис_35-Базис_25)/Базис_25 -> -0.24898934 | G43: =(Базис_45-Базис_35)/Базис_35 -> -0.0046488867 | H43: =(Базис_55-Базис_45)/Базис_45 -> -0.29252704 | I43: =(Базис_65-Базис_55)/Базис_55 -> -0.0086865879 | J43: =(Базис_75-Базис_65)/Базис_65 -> -0.025236593 | K43: =(Базис_85-Базис_75)/Базис_75 -> -0.10751528 | L43: =(Базис_95-Базис_85)/Базис_85 -> -0.20346495 | M43: =(Базис_105-Базис_95)/Базис_95 -> -0.21092564 | N43: =(N7-Базис_105)/Базис_105 -> 0 | O43: =(O7-N7)/N7 -> 1.3136364 | P43: =(P7-O7)/O7 -> 0.70339026 | R43: Нарынская область | T43: =(Базис_Ж_15-Базис_Ж_5)/Базис_Ж_5 -> -0.067419067 | U43: =(Базис_Ж_25-Базис_Ж_15)/Базис_Ж_15 -> 0.025796178 | V43: =(Базис_Ж_35-Базис_Ж_25)/Базис_Ж_25 -> -0.20863086 | W43: =(Базис_Ж_45-Базис_Ж_35)/Базис_Ж_35 -> -0.14397803 | X43: =(Базис_Ж_55-Базис_Ж_45)/Базис_Ж_45 -> -0.3492209 | Y43: =(Базис_Ж_65-Базис_Ж_55)/Базис_Ж_55 -> -0.012676056 | Z43: =(Базис_Ж_75-Базис_Ж_65)/Базис_Ж_65 -> -0.012125535 | AA43: =(Базис_Ж_85-Базис_Ж_75)/Базис_Ж_75 -> -0.11263538 | AB43: =(Базис_Ж_95-Базис_Ж_85)/Базис_Ж_85 -> -0.1903987 | AC43: =(Базис_Ж_105-Базис_Ж_95)/Базис_Ж_95 -> -0.20301508 | AD43: =(AD7-Базис_Ж_105)/Базис_Ж_105 -> 0 | AE43: =(AE7-AD7)/AD7 -> 1.4857274 | AF43: =(AF7-AE7)/AE7 -> 0.70811235 | AH43: Нарынская область | AJ43: =(Базис_М_15-Базис_М_5)/Базис_М_5 -> -0.17799353 | AK43: =(Базис_М_25-Базис_М_15)/Базис_М_15 -> -0.028433946 | AL43: =(Базис_М_35-Базис_М_25)/Базис_М_25 -> -0.30751914 | AM43: =(Базис_М_45-Базис_М_35)/Базис_М_35 -> 0.22626788 | AN43: =(Базис_М_55-Базис_М_45)/Базис_М_45 -> -0.22693531 | AO43: =(Базис_М_65-Базис_М_55)/Базис_М_55 -> -0.0048010974 | AP43: =(Базис_М_75-Базис_М_65)/Базис_М_65 -> -0.037904893 | AQ43: =(Базис_М_85-Базис_М_75)/Базис_М_75 -> -0.10243553 | AR43: =(Базис_М_95-Базис_М_85)/Базис_М_85 -> -0.21628093 | AS43: =(Базис_М_105-Базис_М_95)/Базис_М_95 -> -0.21894094 | AT43: =(AT7-Базис_М_105)/Базис_М_105 -> 0 | AU43: =(AU7-AT7)/AT7 -> 1.1357117 | AV43: =(AV7-AU7)/AU7 -> 0.69770797
...

Sheet Лист2
B1: X | C1: Sin(x) | D1: Cos(x) | E1: Tan(x) | F1: Ln(x) | G1: Log(x) | H1: Корень | I1: Остаток | J1: Нечет | K1: Округ | L1: Отбр | M1: Римское
B2: =RAND()*200 -> 114.39398 | C2: =SIN(B2) -> 0.96265513 | D2: =COS(B2) -> 0.27073068 | E2: =TAN(B2) -> 3.5557667 | F2: =LN(B2) -> 4.7396485 | G2: =LOG10(B2) -> 2.0584032 | H2: =SQRT(B2) -> 10.695512 | I2: =MOD(B2,27) -> 6.3939799 | J2: =ODD(B2) -> 115 | K2: =ROUND(B2,2) -> 114.39 | L2: =TRUNC(B2) -> 114 | M2: =ROMAN(L2) -> CXIV
B3: =RAND()*200 -> 119.06154 | C3: =SIN(B3) -> -0.31359525 | D3: =COS(B3) -> 0.94955675 | E3: =TAN(B3) -> -0.33025435 | F3: =LN(B3) -> 4.7796405 | G3: =LOG10(B3) -> 2.0757715 | H3: =SQRT(B3) -> 10.911533 | I3: =MOD(B3,27) -> 11.061544 | J3: =ODD(B3) -> 121 | K3: =ROUND(B3,2) -> 119.06 | L3: =TRUNC(B3) -> 119 | M3: =ROMAN(L3) -> CXIX
B4: =RAND()*200 -> 180.89285 | C4: =SIN(B4) -> -0.9685971 | D4: =COS(B4) -> 0.24863561 | E4: =TAN(B4) -> -3.8956491 | F4: =LN(B4) -> 5.1979049 | G4: =LOG10(B4) -> 2.2574214 | H4: =SQRT(B4) -> 13.449641 | I4: =MOD(B4,27) -> 18.892849 | J4: =ODD(B4) -> 181 | K4: =ROUND(B4,2) -> 180.89 | L4: =TRUNC(B4) -> 180 | M4: =ROMAN(L4) -> CLXXX
B5: =RAND()*200 -> 34.24748 | C5: =SIN(B5) -> 0.30509559 | D5: =COS(B5) -> -0.95232173 | E5: =TAN(B5) -> -0.32037029 | F5: =LN(B5) -> 3.533613 | G5: =LOG10(B5) -> 1.5346286 | H5: =SQRT(B5) -> 5.8521347 | I5: =MOD(B5,27) -> 7.2474804 | J5: =ODD(B5) -> 35 | K5: =ROUND(B5,2) -> 34.25 | L5: =TRUNC(B5) -> 34 | M5: =ROMAN(L5) -> XXXIV
B6: =RAND()*200 -> 1.6360133 | C6: =SIN(B6) -> 0.99787413 | D6: =COS(B6) -> -0.065170746 | E6: =TAN(B6) -> -15.311688 | F6: =LN(B6) -> 0.49226236 | G6: =LOG10(B6) -> 0.21378683 | H6: =SQRT(B6) -> 1.2790674 | I6: =MOD(B6,27) -> 1.6360133 | J6: =ODD(B6) -> 3 | K6: =ROUND(B6,2) -> 1.64 | L6: =TRUNC(B6) -> 1 | M6: =ROMAN(L6) -> I
B7: =RAND()*200 -> 124.42416 | C7: =SIN(B7) -> -0.94563589 | D7: =COS(B7) -> 0.32522724 | E7: =TAN(B7) -> -2.9076159 | F7: =LN(B7) -> 4.8236964 | G7: =LOG10(B7) -> 2.0949047 | H7: =SQRT(B7) -> 11.154558 | I7: =MOD(B7,27) -> 16.424162 | J7: =ODD(B7) -> 125 | K7: =ROUND(B7,2) -> 124.42 | L7: =TRUNC(B7) -> 124 | M7: =ROMAN(L7) -> CXXIV
B8: =RAND()*200 -> 152.98181 | C8: =SIN(B8) -> 0.8170238 | D8: =COS(B8) -> -0.57660394 | E8: =TAN(B8) -> -1.4169584 | F8: =LN(B8) -> 5.030319 | G8: =LOG10(B8) -> 2.1846398 | H8: =SQRT(B8) -> 12.368582 | I8: =MOD(B8,27) -> 17.98181 | J8: =ODD(B8) -> 153 | K8: =ROUND(B8,2) -> 152.98 | L8: =TRUNC(B8) -> 152 | M8: =ROMAN(L8) -> CLII
B9: =RAND()*200 -> 23.492643 | C9: =SIN(B9) -> -0.99759958 | D9: =COS(B9) -> -0.069246508 | E9: =TAN(B9) -> 14.406497 | F9: =LN(B9) -> 3.1566873 | G9: =LOG10(B9) -> 1.3709319 | H9: =SQRT(B9) -> 4.846921 | I9: =MOD(B9,27) -> 23.492643 | J9: =ODD(B9) -> 25 | K9: =ROUND(B9,2) -> 23.49 | L9: =TRUNC(B9) -> 23 | M9: =ROMAN(L9) -> XXIII
B10: =RAND()*200 -> 195.41462 | C10: =SIN(B10) -> 0.59388234 | D10: =COS(B10) -> 0.8045519 | E10: =TAN(B10) -> 0.73815293 | F10: =LN(B10) -> 5.2751236 | G10: =LOG10(B10) -> 2.2909571 | H10: =SQRT(B10) -> 13.979078 | I10: =MOD(B10,27) -> 6.4146203 | J10: =ODD(B10) -> 197 | K10: =ROUND(B10,2) -> 195.41 | L10: =TRUNC(B10) -> 195 | M10: =ROMAN(L10) -> CXCV
B11: =RAND()*200 -> 71.212313 | C11: =SIN(B11) -> 0.86458187 | D11: =COS(B11) -> -0.50249198 | E11: =TAN(B11) -> -1.7205884 | F11: =LN(B11) -> 4.2656657 | G11: =LOG10(B11) -> 1.8525551 | H11: =SQRT(B11) -> 8.4387388 | I11: =MOD(B11,27) -> 17.212313 | J11: =ODD(B11) -> 73 | K11: =ROUND(B11,2) -> 71.21 | L11: =TRUNC(B11) -> 71 | M11: =ROMAN(L11) -> LXXI
B12: =RAND()*200 -> 164.66986 | C12: =SIN(B12) -> 0.96541908 | D12: =COS(B12) -> 0.26070291 | E12: =TAN(B12) -> 3.7031389 | F12: =LN(B12) -> 5.1039426 | G12: =LOG10(B12) -> 2.2166141 | H12: =SQRT(B12) -> 12.832376 | I12: =MOD(B12,27) -> 2.6698641 | J12: =ODD(B12) -> 165 | K12: =ROUND(B12,2) -> 164.67 | L12: =TRUNC(B12) -> 164 | M12: =ROMAN(L12) -> CLXIV
B13: =RAND()*200 -> 79.26996 | C13: =SIN(B13) -> -0.66697677 | D13: =COS(B13) -> -0.74507851 | E13: =TAN(B13) -> 0.8951765 | F13: =LN(B13) -> 4.3728592 | G13: =LOG10(B13) -> 1.8991086 | H13: =SQRT(B13) -> 8.9033679 | I13: =MOD(B13,27) -> 25.26996 | J13: =ODD(B13) -> 81 | K13: =ROUND(B13,2) -> 79.27 | L13: =TRUNC(B13) -> 79 | M13: =ROMAN(L13) -> LXXIX
... B26: =RAND()*200 -> 124.01214 | C26: =SIN(B26) -> -0.99673967 | D26: =COS(B26) -> -0.08068476 | E26: =TAN(B26) -> 12.353506 | F26: =LN(B26) -> 4.8203794 | G26: =LOG10(B26) -> 2.0934642 | H26: =SQRT(B26) -> 11.136074 | I26: =MOD(B26,27) -> 16.012137 | J26: =ODD(B26) -> 125 | K26: =ROUND(B26,2) -> 124.01 | L26: =TRUNC(B26) -> 124 | M26: =ROMAN(L26) -> CXXIV
A27: Сумма | B27: =SUM(B2:B26) -> 2540.1967 | C27: =SUM(C2:C26) -> 0.93219945 | D27: =SUM(D2:D26) -> -0.34486486 | E27: =SUM(E2:E26) -> -104.07679 | F27: =SUM(F2:F26) -> 105.58843 | G27: =SUM(G2:G26) -> 45.856472 | H27: =SUM(H2:H26) -> 234.52253 | I27: =SUM(I2:I26) -> 326.19672 | ... L27: =SUM(L2:L26) -> 2526
A28: Среднее | B28: =AVERAGE(B2:B26) -> 101.60787 | C28: =AVERAGE(C2:C26) -> 0.037287978 | D28: =AVERAGE(D2:D26) -> -0.013794595 | E28: =AVERAGE(E2:E26) -> -4.1630715 | F28: =AVERAGE(F2:F26) -> 4.2235372 | G28: =AVERAGE(G2:G26) -> 1.8342589 | H28: =AVERAGE(H2:H26) -> 9.3809011 | I28: =AVERAGE(I2:I26) -> 13.047869 | ... L28: =AVERAGE(L2:L26) -> 101.04
