Workbook

Sheet Экзамен
A3: № | B3: Фамилия | C3: Математика | D3: Информатика | E3: Философия | F3: Культурология | G3: Стипендия | I3: № | J3: Фамилия | K3: Математика | L3: Информатика | M3: Философия | N3: Культурология | O3: Стипендия
A4: 1 | B4: Агафонова | C4: 3 | D4: 4 | E4: 4 | F4: 3 | L4: 4
A5: 2 | B5: Алиев | C5: 5 | D5: 5 | E5: 5 | F5: 5 | G5: 500 | I5: № | J5: Фамилия | K5: Математика | L5: Информатика | M5: Философия | N5: Культурология | O5: Стипендия
A6: 3 | B6: Аллабердиева | C6: 5 | D6: 5 | E6: 3 | F6: 3 | K6: 3
A7: 4 | B7: Аллаярова | C7: 4 | D7: 4 | E7: 5 | F7: 5 | G7: 350 | L7: 3
A8: 5 | B8: Асанов | C8: 4 | D8: 4 | E8: 5 | F8: 5 | G8: 350 | M8: 3
A9: 6 | B9: Бозоева | C9: 5 | D9: 4 | E9: 4 | F9: 4 | G9: 300 | N9: 3
A10: 7 | B10: Габибова | C10: 5 | D10: 5 | E10: 5 | F10: 4 | G10: 400 | I10: № | J10: Фамилия | K10: Математика | L10: Информатика | M10: Философия | N10: Культурология | O10: Стипендия
A11: 8 | B11: Ганзий | C11: 3 | D11: 3 | E11: 4 | F11: 3 | L11: 2
A12: 9 | B12: Дегенбаев | C12: 5 | D12: 5 | E12: 5 | F12: 5 | G12: 500 | I12: № | J12: Фамилия | K12: Математика | L12: Информатика | M12: Философия | N12: Культурология | O12: Стипендия
A13: 10 | B13: Дулатов | C13: 5 | D13: 4 | E13: 4 | F13: 3 | L13: 4 | M13: 5
A14: 11 | B14: Жылтыров | C14: 4 | D14: 4 | E14: 4 | F14: 4 | G14: 250
A15: 13 | B15: Исабекова | C15: 5 | D15: 5 | E15: 5 | F15: 4 | G15: 400
A16: 14 | B16: Исаева | C16: 5 | D16: 4 | E16: 4 | F16: 4 | G16: 300
A17: 15 | B17: Исматуллаева | C17: 4 | D17: 4 | E17: 5 | F17: 4 | G17: 300
A18: 16 | B18: Каландарова | C18: 5 | D18: 3 | E18: 3 | F18: 5
A19: 17 | B19: Караева | C19: 4 | D19: 4 | E19: 4 | F19: 4 | G19: 250
A20: 18 | B20: Командирова | C20: 3 | D20: 4 | E20: 3 | F20: 5
A21: 19 | B21: Кондратьева | C21: 5 | D21: 4 | E21: 3 | F21: 5 | G21: 300
A22: 20 | B22: Лоу | C22: 5 | D22: 5 | E22: 4 | F22: 4 | G22: 350
A23: 21 | B23: Парфенова | C23: 5 | D23: 3 | E23: 3 | F23: 3
A24: 22 | B24: Проскурина | C24: 3 | D24: 5 | E24: 3 | F24: 4
A25: 23 | B25: Руденко | C25: 3 | D25: 2 | E25: 3 | F25: 4
A26: 24 | B26: Рыштакова | C26: 5 | D26: 4 | E26: 4 | F26: 3
A27: 26 | B27: Саламатова | C27: 4 | D27: 5 | E27: 5 | F27: 4 | G27: 350
A28: 27 | B28: Ситникова | C28: 5 | D28: 4 | E28: 5 | F28: 5 | G28: 400
A29: 28 | B29: Сметанкина | C29: 5 | D29: 3 | E29: 5 | F29: 3
A30: 29 | B30: Степаненко | C30: 4 | D30: 4 | E30: 4 | F30: 4 | G30: 250
A31: 30 | B31: Сулайманова | C31: 4 | D31: 4 | E31: 3 | F31: 3
A32: 31 | B32: Сулумова | C32: 4 | D32: 4 | E32: 4 | F32: 5 | G32: 300
A33: 32 | B33: Цой | C33: 3 | D33: 4 | E33: 5 | F33: 4
A36: Задание 1
A37: Среднее значение стипендии
A38: =DAVERAGE(A3:G33,"Стипендия ",L3:L4) -> 304.54545
A40: Число студентов с хотя бы одной тройкой:
A41: =DCOUNTA(A3:G33,"Фамилия",K5:N9) -> 14
A43: Студент, получивший по информатике 2:
A44: № | B44: Фамилия | C44: Математика | D44: Информатика | E44: Философия | F44: Культурология
A45: =DGET(A3:G33,"№",L10:L11) -> 23 | B45: =DGET(A3:G33,"Фамилия",L10:L11) -> Руденко | C45: =DGET(A3:G33,"Математика",L10:L11) -> 3 | D45: =DGET(A3:G33,"Информатика",L10:L11) -> 2 | E45: =DGET(A3:G33,"Философия",L10:L11) -> 3 | F45: =DGET(A3:G33,"Культурология",L10:L11) -> 4
A47: Максимальная стипендия
...

Sheet Консолидация
A1: Категории | C1: Закупка
B2: Лаб_13 | C2: =Альфа!$B$2 -> 14902
C3: =Альфа!$B$28 -> 23182
C4: =Альфа!$B$54 -> 15475
C5: =Альфа!$B$80 -> 14470
C6: =Альфа!$B$106 -> 10881
C7: =Альфа!$B$133 -> 17343
C8: =Альфа!$B$160 -> 15420
C9: =Альфа!$B$186 -> 10522
C10: =Альфа!$B$212 -> 12621
C11: =Альфа!$B$238 -> 10299
C12: =Альфа!$B$265 -> 10607
C13: =Альфа!$B$291 -> 16610
C14: =Альфа!$B$317 -> 13833
C15: =Альфа!$B$343 -> 13628
C16: =Альфа!$B$369 -> 8316
C17: =Альфа!$B$396 -> 9156.36
C18: =Альфа!$B$422 -> 12194.75
C19: =Альфа!$B$447 -> 11282.79
C20: =Альфа!$B$472 -> 7597.54
C21: =Альфа!$B$498 -> 18839.04
C22: =Альфа!$B$523 -> 10591.54
C23: =Альфа!$B$548 -> 8426
C24: =Альфа!$B$572 -> 5242.43
C25: =Альфа!$B$598 -> 8424.95
C26: =Альфа!$B$622 -> 8435.98
C27: =Альфа!$B$647 -> 13151.95
C28: =Альфа!$B$672 -> 16477.94
C29: =Альфа!$B$697 -> 3230.97
C30: =Альфа!$B$723 -> 8339.94
C31: =Альфа!$B$746 -> 7776.95
C32: =Альфа!$B$772 -> 9018
C33: =Альфа!$B$795 -> 16160.98
C34: =Альфа!$B$820 -> 8384.99
C35: =Альфа!$B$844 -> 14994.98
C36: =Альфа!$B$869 -> 14513.99
C37: =Альфа!$B$894 -> 12629.99
C38: =Альфа!$B$919 -> 6728
C39: =Альфа!$B$944 -> 9848
C40: =Альфа!$B$969 -> 5874.99
...

Sheet Альфа
A1: Подгруппа | B1: Закупка
A2: Хлеб,хлебопродукты | B2: 14902
A3: Выпечка | B3: 354936.41
A4: Кондитерские изделия | B4: 150821.01
A5: Дието-, диабетические продукты | B5: 6301
A6: Детское питание | B6: 5402
A7: Кофе, кофейные напитки, чай | B7: 219822.79
A8: Бакалея | B8: 846540.17
A9: Консервы | B9: 155003.84
A10: Растительные масла,специи,соусы | B10: 264540.7
A11: Алкогольные напитки, пиво | B11: 1642185.4
A12: Безалкогольные напитки | B12: 198209.29
A13: Соки | B13: 213525.01
... A1244: Бытовая химия | B1244: 419762.67

Sheet Бета
A1: Подгруппа | B1: Закупка
A2: Хлеб,хлебопродукты | B2: 2213
A3: Выпечка | B3: 51615.08
A4: Кондитерские изделия | B4: 37470.24
A5: Дието-, диабетические продукты | B5: 1286
A6: Детское питание | B6: 6477.89
A7: Кофе, кофейные напитки, чай | B7: 113014.8
A8: Бакалея | B8: 407615.55
A9: Консервы | B9: 28027
A10: Растительные масла,специи,соусы | B10: 72917.29
A11: Алкогольные напитки, пиво | B11: 108895.48
A12: Безалкогольные напитки | B12: 50113.52
A13: Соки | B13: 42579
... A1018: Бытовая химия | B1018: 39014.42

Sheet Гамма
A1: Подгруппа | B1: Закупка
A2: Хлеб,хлебопродукты | B2: 11892
A3: Выпечка | B3: 247618.59
A4: Кондитерские изделия | B4: 102169.72
A5: Дието-, диабетические продукты | B5: 3142
A6: Детское питание | B6: 8925.64
A7: Кофе, кофейные напитки, чай | B7: 178547.47
A8: Бакалея | B8: 542280.33
A9: Консервы | B9: 173640.96
A10: Растительные масла,специи,соусы | B10: 229364.07
A11: Алкогольные напитки, пиво | B11: 418815.5
A12: Безалкогольные напитки | B12: 150539.4
A13: Соки | B13: 66334
... A1262: Бытовая химия | B1262: 248030.57

Sheet Дельта
A1: Подгруппа | B1: Закупка
A2: Хлеб,хлебопродукты | B2: 16764
A3: Выпечка | B3: 203581.19
A4: Кондитерские изделия | B4: 84532.1
A5: Дието-, диабетические продукты | B5: 3298
A6: Детское питание | B6: 34836.87
A7: Кофе, кофейные напитки, чай | B7: 125858.47
A8: Бакалея | B8: 447084.74
A9: Консервы | B9: 108571.97
A10: Растительные масла,специи,соусы | B10: 178209.93
A11: Алкогольные напитки, пиво | B11: 334985.94
A12: Безалкогольные напитки | B12: 114554.73
A13: Соки | B13: 129453.31
... A1256: Бытовая химия | B1256: 185261

Sheet Консолидация 2
A1: Страница1 | B1: (Все)
A3: Сумма по полю Значение | B3: Названия столбцов
A4: Названия строк | B4: Закупка | C4: Общий итог
A5: Алкогольные напитки, пиво | B5: 71919466 | C5: 71919466
A6: Бакалея | B6: 88001318 | C6: 88001318
A7: Безалкогольные напитки | B7: 28968102 | C7: 28968102
A8: Бытовая химия | B8: 50782859 | C8: 50782859
A9: Выпечка | B9: 39433728 | C9: 39433728
A10: Детское питание | B10: 1253999.9 | C10: 1253999.9
A11: Дието-, диабетические продукты | B11: 293057.15 | C11: 293057.15
A12: Замороженные продукты | B12: 15278209 | C12: 15278209
A13: Кондитерские изделия | B13: 16863274 | C13: 16863274
A14: Консервы | B14: 20163161 | C14: 20163161
A15: Косметика и парфюмерия | B15: 28220440 | C15: 28220440
A16: Кофе, кофейные напитки, чай | B16: 24642954 | C16: 24642954
... A32: Общий итог | B32: 7.3495355e+08 | C32: 7.3495355e+08
